Workbook

Sheet Isopo
A1: Clause ID | B1: Clause | C1: Translation | D1: Predicate | E1: Pred Type | F1: ~Ø-Verbal | G1: ACT-ARG | H1: NON-ARG | I1: EXALT INSIG | J1: V-ARG-Ø-ARG | K1: GAP-NON-ARG | L1: GAP-ACT-ARG | M1: NMLZ head | N1: NOM EXH MORPH | O1: Сomment
A2: EF1 | B2: EVROPA no vchi Phrigiatoyŭ cunino Troia toyŭ jŏrino qinpenni Amoniato yŭ ſatoga vogiaru. | C2: ＥＶＲＯＰＡの内Ｐｈｒｉｇｉａと言う国のＴｒｏｉａと言う城裡の近辺にＡｍｏｎｉａと言う里がおぢゃる | D2: vogiaru | E2: FV | F2: 1 | G2: 1 | H2: 1 | I2: 0 | J2: 0 | K2: 0 | L2: 0 | M2: 0 | N2: 0
A3: EF2 | B3: [...] nauoba Eſopoto yŭte | C3: その里に名をばＥｓｏｐｏと言うて | D3: yŭte | E3: FV | F3: 1 | G3: 1 | H3: 0 | I3: 0 | J3: 0 | K3: 0 | L3: 0 | M3: 0 | N3: 0
A4: EF3 | B4: [Sono ſatoni] yguiŏ fuxiguina jintaiga vogiattaga | C4: 異形不思議な人体がおぢゃったが | D4: vogiattaga | E4: FV | F4: 1 | G4: 1 | H4: 1 | I4: 0 | J4: 0 | K4: 0 | L4: 0 | M4: 0 | N4: 0
A5: EF4 | B5: [...] cono fitoni maſatte | C5: Ｅｕｒｏｐａの天下にこの人に勝って | D5: maſatte | E5: FV | F5: 1 | G5: 1 | H5: 0 | I5: 0 | J5: 0 | K5: 0 | L5: 0 | M5: 0 | N5: 0
A6: EF5 | B6: [ſono jidai Europano tencani] minicui mo nomo vorinacatta | C6: 醜い者もおりなかった | D6: vorinacatta | E6: FV | F6: 1 | G6: 2 | H6: 1 | I6: 0 | J6: 0 | K6: 0 | L6: 0 | M6: 0 | N6: 0 | O6: is oru an EX verb in LMJ?
A7: EF6 | B7: to qicoyeta | C7: と聞こえた | D7: qicoyeta | E7: FV | F7: 1 | G7: 1 | H7: 0 | I7: 0 | J7: 0 | K7: 0 | L7: 0 | M7: 0 | N7: 0
A8: EF7 | B8: Mazzu cŏbeua togari | C8: 先づ頭は尖り， | D8: togari | E8: FV | F8: 1 | G8: 1 | H8: 0 | I8: 0 | J8: 0 | K8: 0 | L8: 0 | M8: 0 | N8: 0
A9: EF8 | B9: manacoua tçubô xicamo dete | C9: 眼はつぼう然も出て | D9: dete | E9: FV | F9: 1 | G9: 1 | H9: 0 | I9: 0 | J9: 0 | K9: 0 | L9: 0 | M9: 0 | N9: 0
A10: EF9 | B10: fitomi no ſaqiua tairacani, | C10: 瞳の先は平らかに， | D10: tairacani | E10: COP | F10: 1 | G10: 1 | H10: =-I98 -> 0 | I10: 0 | J10: 0 | K10: 0 | L10: 0 | M10: 0 | N10: 0
A11: EF10 | B11: riŏno fôua tare | C11: 両の頬は垂れ | D11: tare | E11: FV | F11: 1 | G11: 1 | H11: 0 | I11: 0 | J11: 0 | K11: 0 | L11: 0 | M11: 0 | N11: 0
A12: EF11 | B12: cubiua yugami | C12: 首は歪み | D12: yugami | E12: FV | F12: 1 | G12: 1 | H12: 0 | I12: 0 | J12: 0 | K12: 0 | L12: 0 | M12: 0 | N12: 0
A13: EF12 | B13: taqe-ua ficŭ | C13: 丈は低う | D13: ficŭ | E13: FV | F13: 1 | G13: 1 | H13: 0 | I13: 0 | J13: 0 | K13: 0 | L13: 0 | M13: 0 | N13: 0
A14: EF13 | B14: yocobarini,xeua cugumi | C14: 横張りに，背は屈み | D14: cugumi | E14: FV | F14: 1 | G14: 1 | H14: 0 | I14: 0 | J14: 0 | K14: 0 | L14: 0 | M14: 0 | N14: 0
A15: EF14 | B15: faraua fare | C15: 腹は腫れ | D15: fare | E15: FV | F15: 1 | G15: 1 | H15: 0 | I15: 0 | J15: 0 | K15: 0 | L15: 0 | M15: 0 | N15: 0
A16: EF15 | B16: taredete | C16: 垂れ出て | D16: taredete | E16: FV | F16: 1 | G16: 0 | H16: 0 | I16: 0 | J16: 0 | K16: 0 | L16: 0 | M16: 0 | N16: 0
A17: EF16 | B17: cotobaua domoride vogiatta | C17: 言葉は吃りでおぢゃった | D17: de vogiatta | E17: COP | F17: 1 | G17: 1 | H17: 0 | I17: 0 | J17: 0 | K17: 0 | L17: 0 | M17: 0 | N17: 0
A18: EF17 | B18: Corerano ſugata vomotte | C18: これ等の姿を持って | D18: vomotte | E18: FV | F18: 1 | G18: 1 | H18: 0 | I18: 0 | J18: 0 | K18: 0 | L18: 0 | M18: 0 | N18: 0
A19: EF18 | B19: minicui coto tenca busŏ de atta | C19: 醜い事天下無双で有った | D19: de atta | E19: COP | F19: 1 | G19: 1 | H19: 1 | I19: 0 | J19: 0 | K19: 0 | L19: 0 | M19: 0 | N19: 0
A20: EF19 | B20: gotoqu chiyeno taqeta | C20: ごとく，知恵の長けた | D20: yararureba | E20: FV | F20: 1 | G20: 1 | H20: 1 | I20: 0 | J20: 0 | K20: 0 | L20: 0 | M20: 0 | N20: 0
A21: EF20 | B21: monomo cono fitoni narabu | C21: 者もこの人に並ぶ | D21: narabu | E21: FV | F21: 1 | G21: 2 | H21: 0 | I21: 0 | J21: 0 | K21: 1 | L21: 0 | M21: 0 | N21: 0
A22: EF21 | B22: cotoua vorinacatta | C22: 事はおりなかった | D22: vorinacatta | E22: FV | F22: 1 | G22: 1 | H22: 0 | I22: 0 | J22: 0 | K22: 0 | L22: 0 | M22: 0 | N22: 0
... A24: EF23 | B24: yŏ-ua:cugaino ſabaqi aruiua naixôno toriatçucai nadoua icanimo niyŏmajij | C24: 様は：公界の捌き或いは内証の取り扱いなどは如何にも似合うまじい | D24: niyŏmajij | E24: FV | F24: 1 | G24: 1 | H24: 1 | I24: 0 | J24: 0 | K24: 0 | L24: 0 | M24: 0 | N24: 0
A25: EF24 | B25: to miyureba | C25: と見ゆれば | D25: miyureba | E25: FV | F25: 1 | G25: 1 | H25: 0 | I25: 0 | J25: 0 | K25: 0 | L25: 0 | M25: 0 | N25: 0 | O25: should the -to part be considered a clausal subject of miyureba?
A26: EF25 | B26: xemete nônin no xoſauo naritomo ategauŏzu | C26: せめて農人の所作をなりともあてがわうず | D26: ategauŏzu | E26: FV | F26: 1 | G26: 1 | H26: 0 | I26: 0 | J26: 0 | K26: 0 | L26: 0 | M26: 0 | N26: 0
A27: EF26 | B27: to vomoi ſadame | C27: と思い定め | D27: vomoi ſadame | E27: FV | F27: 1 | G27: 1 | H27: 0 | I27: 0 | J27: 0 | K27: 0 | L27: 0 | M27: 0 | N27: 0 | O27: should the -to part be considered a clausal subject?
A28: EF27 | B28: nôguuo coxiraye atayete | C28: 農具を拵え与えて | D28: atayete | E28: FV | F28: 1 | G28: 1 | H28: 0 | I28: 0 | J28: 0 | K28: 0 | L28: 0 | M28: 0 | N28: 0
A29: EF28 | B29: denbacu ye yararureba | C29: 田畠へ遣らるれば | D29: yararureba | E29: FV | F29: 1 | G29: 1 | H29: 0 | I29: 0 | J29: 1 | K29: 0 | L29: 0 | M29: 0 | N29: 0
A30: EF29 | B30: Eſopomomata cocoroyogueni ſono xoſauo naita | C30: Ｅｓｏｐｏも又快気にその所作を成いた． | D30: naita | E30: FV | F30: 1 | G30: 2 | H30: 0 | I30: 0 | J30: 0 | K30: 0 | L30: 0 | M30: 0 | N30: 0
A31: EF30 | B31: Xicareba fodofete cano xujin ſono denbacu uo mimaini ideraretareba | C31: 然れば程経てかの主人その田畠を見舞いに出でられたれば | D31: ideraretareba | E31: FV | F31: 1 | G31: 2 | H31: 0 | I31: 1 | J31: 0 | K31: 0 | L31: 0 | M31: 0 | N31: 0
A32: EF31 | B32: aru fiacuxŏ jŏjŏno jucuxiuo motteqite | C32: 或る百姓上々の熟柿を持って来て | D32: motteqite | E32: FV | F32: 1 | G32: 2 | H32: 0 | I32: 0 | J32: 0 | K32: 0 | L32: 0 | M32: 0 | N32: 0
A33: EF32 | B33: xujinni ſaſagureba | C33: 主人に捧ぐれば | D33: ſaſagureba | E33: FV | F33: 1 | G33: 1 | H33: 0 | I33: 0 | J33: 1 | K33: 0 | L33: 0 | M33: 0 | N33: 0
A34: EF33 | B34: irocamo ychidan yôte | C34: 色香も一段良うて | D34: yôte | E34: FV | F34: 1 | G34: 1 | H34: 0 | I34: 0 | J34: 0 | K34: 0 | L34: 0 | M34: 0 | N34: 0
A35: EF34 | B35: migotoniatta | C35: 見事に有った | D35: niatta | E35: COP | F35: 1 | G35: 0 | H35: 0 | I35: 0 | J35: 0 | K35: 0 | L35: 0 | M35: 0 | N35: 0
A36: EF35 | B36: ni yotte yorocobi | C36: に因って喜び | D36: yorocobi | E36: FV | F36: 1 | G36: 0 | H36: 1 | I36: 0 | J36: 0 | K36: 0 | L36: 0 | M36: 0 | N36: 0
A37: EF36 | B37: nanome narananda | C37: 斜めならなんだ | D37: narananda | E37: COP | F37: 1 | G37: 0 | H37: 0 | I37: 0 | J37: 0 | K37: 0 | L37: 0 | M37: 0 | N37: 0
A38: EF37 | B38: tadaima xŏquan xôzuredomo | C38: 只今賞翫せうずれども | D38: xôzuredomo | E38: VN-C (bare) | F38: 1 | G38: 0 | H38: 1 | I38: 0 | J38: 0 | K38: 0 | L38: 0 | M38: 0 | N38: 0
A39: EF38 | B39: furoye ireba | C39: 風呂へ入れば | D39: ireba | E39: FV | F39: 1 | G39: 1 | H39: 0 | I39: 0 | J39: 0 | K39: 0 | L39: 0 | M39: 0 | N39: 0
... A64: EF63 | B64: icaſama cono tatari ga arŏzu | C64: 如何様この祟りが有らうずと | D64: arŏzuto | E64: FV | F64: 1 | G64: 1 | H64: 0 | I64: 0 | J64: 0 | K64: 0 | L64: 0 | M64: 0 | N64: 0
A65: EF64 | B65: to ſaſayaqimauatta | C65: 囁き回った | D65: ſaſayaqimauatta | E65: FV | F65: 1 | G65: 1 | H65: 0 | I65: 0 | J65: 0 | K65: 0 | L65: 0 | M65: 0 | N65: 0 | O65: should the -to part be considered a clausal complement?
...

Sheet Heike Chapter 2
A1: HeikeCh2 | C1: Translation | D1: Predicate | E1: Modality | F1: Verb_Semantic_Class | G1: Pred_Type | H1: Predicate_Transitivity | I1: Voice_Type | J1: Clause_Polarity | K1: ~Ø-Verbal | L1: ACT-ARG | M1: Arg Type | N1: NON-ARG | O1: Subject_Class | P1: Subject_Person | Q1: Object_Class | R1: Indirect_Object_Class | S1: GAP-ACT-ARG | T1: GAP-NON-ARG | U1: Adnominal_Function | V1: Clause_Type | W1: EXALT INSIG | X1: V-ARG-Ø-ARG | Y1: Exaltation_Referential_Target | Z1: Exaltation_Form_Type | AA1: NOM EXH MORPH | AB1: Connective_Type | AC1: Prev_Clause_Type | AD1: Te_Position | AE1: Switch_Ref | AF1: Next_Switch_Ref | AG1: Topic_Status | AH1: Information_Status | AI1: Сomment | AK1: RD2 | AL1: LVC | AM1: Subject_Zero | AN1: Sentence_ID | AO1: Next_Clause_Type | AP1: Is_ChainClause | AQ1: Chain_Index_In_Sentence | AR1: Is_First_ChainClause | AS1: Next_Subject_Classt | AT1: Next_Object_Classt | AU1: Drop_Subject (overt → zero in next clause) | AV1: Drop_Object (overt → zero in next clause)
A2: Heike 2.1 | B2: 忠盛朝臣未だ備前守たりし時 (Tadamori ason imada Bizen no kami tarishi toki) | C2: Now Tadamori, while holding the office of Bizen no Kami, | D2: たりし | E2: indicative | F2: stative | G2: copula | H2: intransitive | I2: active | J2: positive | K2: 1 | L2: 1 | M2: SUB | N2: 0 | O2: overt | P2: 3 | Q2: n/a | R2: n/a | S2: 0 | T2: 1 | U2: REL | V2: relative | W2: 0 | X2: 0 | Y2: n/a | Z2: n/a | AA2: 0 | AB2: temporal | AD2: =IF(V2<>"te","", IF(OR(AC2="",AC2<>"te"), "te_initial", "te_medial")) | AE2: new | AF2: ss | AG2: topic-introduced | AH2: contains_new | AK2: =L2/K2 -> 1 | AL2: =IF(OR(G2="LVC", G2="LVC (j)", G2="LVC (inf)"), "LVC","non-LVC") -> non-LVC | AM2: {=IF(OR(O2:O159="zero_recoverable", "zero_exalt", "zero_other", "zero_uncertain"), "Yes","No")} -> Yes | AN2: =1 + COUNTIF($V1:V$2,"main") -> 1 | AO2: =IF($A2="","",IF($AH2=$AH3,$V3,"")) -> te | AP2: =IF(OR($V2="relative",$V2="nominalised"),0,1) -> 0 | AQ2: =IF(AP3=0,"",COUNTIFS($AN$2:$AN3,$AN3,$AP$2:$AP3,1)) -> 1 | AR2: =IF(AQ2=1,1,0) -> 1 | AS2: zero_recoverable | AT2: overt | AU2: =IF(AND($O2="overt",LEFT($AS2,5)="zero_"),1,0) -> 1 | AV2: =IF(AND($Q2="overt",LEFT($AT2,5)="zero_"),1,0) -> 0
A3: Heike 2.2 | B3: 鳥羽院の御願得長寿院を造進して (Toba-in no ogan Tokuchōju-in o zōshin shite) | C3: by the request of the retired Emperor Toba, | D3: 造進して | E3: indicative | F3: other | G3: verb | H3: transitive | I3: active | J3: positive | K3: 1 | L3: 1 | M3: OBJ | N3: 1 | O3: zero_recoverable | P3: 3 | Q3: overt | R3: n/a | S3: 0 | T3: 0 | U3: n/a | V3: te | W3: 0 | X3: 0 | Y3: obj | Z3: nominal_prefix | AA3: 1 | AB3: sequential | AC3: relative | AD3: te_medial | AE3: ss | AF3: ss | AG3: topic-drop | AH3: contains_new | AI3: stranded subject Tadamori | AK3: =L3/K3 -> 1 | AL3: =IF(OR(G3="LVC", G3="LVC (j)", G3="LVC (inf)"), "LVC","non-LVC") -> non-LVC | AM3: {=IF(OR(O3:O160="zero_recoverable", "zero_exalt", "zero_other", "zero_uncertain"), "Yes","No")} -> Yes | AN3: =1 + COUNTIF($V2:V$2,"main") -> 1 | AO3: =IF($A3="","",IF($AH3=$AH4,$V4,"")) -> te | AP3: =IF(OR($V3="relative",$V3="nominalised"),0,1) -> 1 | AQ3: =IF(AP4=0,"",COUNTIFS($AN$2:$AN4,$AN4,$AP$2:$AP4,1)) -> 2 | AR3: =IF(AQ3=1,1,0) -> 0 | AS3: zero_recoverable | AT3: overt | AU3: =IF(AND($O3="overt",LEFT($AS3,5)="zero_"),1,0) -> 0 | AV3: =IF(AND($Q3="overt",LEFT($AT3,5)="zero_"),1,0) -> 0
A4: Heike 2.3 | B4: 三十三間の御堂を建て (sanjūsangen no midō o tatete) | C4: had built the temple Toku-cho-juin and the Sa-ju-san-gen-do, or hall 33 ken long, | D4: 建て | E4: indicative | F4: other | G4: verb | H4: transitive | I4: active | J4: positive | K4: 1 | L4: 1 | M4: OBJ | N4: 0 | O4: zero_recoverable | P4: 3 | Q4: overt | R4: n/a | S4: 0 | T4: 0 | U4: n/a | V4: te | W4: 0 | X4: 0 | Y4: obj | Z4: nominal_prefix | AA4: 1 | AB4: sequential | AC4: te | AD4: =IF(V4<>"te","", IF(OR(AC4="",AC4<>"te"), "te_initial", "te_medial")) -> te_medial | AE4: ss | AF4: ss | AG4: topic-drop | AH4: contains_new | AK4: =L4/K4 -> 1 | AL4: =IF(OR(G4="LVC", G4="LVC (j)", G4="LVC (inf)"), "LVC","non-LVC") -> non-LVC | AM4: {=IF(OR(O4:O161="zero_recoverable", "zero_exalt", "zero_other", "zero_uncertain"), "Yes","No")} -> Yes | AN4: =1 + COUNTIF($V$2:V3,"main") -> 1 | AO4: =IF($A4="","",IF($AH4=$AH5,$V5,"")) -> relative | AP4: =IF(OR($V4="relative",$V4="nominalised"),0,1) -> 1 | AQ4: =IF(AP5=0,"",COUNTIFS($AN$2:$AN5,$AN5,$AP$2:$AP5,1)) | AR4: =IF(AQ4=1,1,0) -> 0 | AS4: zero_exalt | AT4: overt | AU4: =IF(AND($O4="overt",LEFT($AS4,5)="zero_"),1,0) -> 0 | AV4: =IF(AND($Q4="overt",LEFT($AT4,5)="zero_"),1,0) -> 0
A5: Heike 2.4 | B5: 一千一体の御仏を据ゑ奉らる (issen ittai no mihotoke o sue-tatematsuraru) | C5: within which were one thousand and one Buddhas; | D5: 据ゑ奉らる | E5: indicative | F5: action | G5: verb | H5: transitive | I5: active | J5: positive | K5: 1 | L5: 1 | M5: OBJ | N5: 0 | O5: zero_exalt | P5: 3 | Q5: overt | R5: n/a | S5: 0 | T5: 1 | U5: REL | V5: relative | W5: 1 | X5: 1 | Y5: sub | Z5: honorific_aux | AA5: 1 | AB5: none | AC5: te | AD5: =IF(V5<>"te","", IF(OR(AC5="",AC5<>"te"), "te_initial", "te_medial")) | AE5: ss | AF5: ds | AG5: topic-drop | AH5: contains_new | AI5: complex verbal form | AK5: =L5/K5 -> 1 | AL5: =IF(OR(G5="LVC", G5="LVC (j)", G5="LVC (inf)"), "LVC","non-LVC") -> non-LVC | AM5: {=IF(OR(O5:O162="zero_recoverable", "zero_exalt", "zero_other", "zero_uncertain"), "Yes","No")} -> Yes | AN5: =1 + COUNTIF($V$2:V4,"main") -> 1 | AO5: =IF($A5="","",IF($AH5=$AH6,$V6,"")) -> main | AP5: =IF(OR($V5="relative",$V5="nominalised"),0,1) -> 0 | AQ5: =IF(AP6=0,"",COUNTIFS($AN$2:$AN6,$AN6,$AP$2:$AP6,1)) -> 3 | AR5: =IF(AQ5=1,1,0) -> 0 | AS5: overt | AT5: n/a | AU5: =IF(AND($O5="overt",LEFT($AS5,5)="zero_"),1,0) -> 0 | AV5: =IF(AND($Q5="overt",LEFT($AT5,5)="zero_"),1,0) -> 0
A6: Heike 2.5 | B6: 供養は天承元年三月十三日なり (kuyō wa Tenshō gannen sangatsu jūsan-nichi nari) | C6: its first festival being on the thirteenth day of the third month of the first year of Tensho. | D6: なり | E6: indicative | F6: stative | G6: copula | H6: intransitive | I6: active | J6: positive | K6: 1 | L6: 1 | M6: SUB | N6: 0 | O6: overt | P6: 3 | Q6: n/a | R6: n/a | S6: 0 | T6: 0 | U6: n/a | V6: main | W6: 0 | X6: 0 | Y6: n/a | Z6: n/a | AA6: 0 | AB6: none | AC6: relative | AD6: =IF(V6<>"te","", IF(OR(AC6="",AC6<>"te"), "te_initial", "te_medial")) | AE6: ds | AF6: ds | AG6: topic-introduced | AH6: contains_new | AK6: =L6/K6 -> 1 | AL6: =IF(OR(G6="LVC", G6="LVC (j)", G6="LVC (inf)"), "LVC","non-LVC") -> non-LVC | AM6: {=IF(OR(O6:O163="zero_recoverable", "zero_exalt", "zero_other", "zero_uncertain"), "Yes","No")} -> Yes | AN6: =1 + COUNTIF($V$2:V5,"main") -> 1 | AO6: =IF($A6="","",IF($AH6=$AH7,$V7,"")) -> subordinate | AP6: =IF(OR($V6="relative",$V6="nominalised"),0,1) -> 1 | AQ6: =IF(AP7=0,"",COUNTIFS($AN$2:$AN7,$AN7,$AP$2:$AP7,1)) -> 1 | AR6: 0 | AS6: zero_exalt | AT6: overt | AU6: =IF(AND($O6="overt",LEFT($AS6,5)="zero_"),1,0) -> 1 | AV6: =IF(AND($Q6="overt",LEFT($AT6,5)="zero_"),1,0) -> 0
A7: Heike 2.6 | B7: 勧賞には欠国を賜ふべき由 (kanshō ni wa kakukuni o tamau beki yoshi) | C7: As a reward he was to be granted a fief, | D7: 賜ふべき | E7: deontic | F7: action | G7: verb | H7: transitive | I7: active | J7: positive | K7: 1 | L7: 1 | M7: OBJ | N7: 1 | O7: zero_exalt | P7: 3 | Q7: overt | R7: n/a | S7: 0 | T7: 1 | U7: n/a | V7: subordinate | W7: 0 | X7: 1 | Y7: sub | Z7: lexical_honorific_verb | AA7: 0 | AB7: causal | AC7: main | AD7: =IF(V7<>"te","", IF(OR(AC7="",AC7<>"te"), "te_initial", "te_medial")) | AE7: ds | AF7: ds | AG7: topic-shift | AH7: contains_new | AK7: =L7/K7 -> 1 | AL7: =IF(OR(G7="LVC", G7="LVC (j)", G7="LVC (inf)"), "LVC","non-LVC") -> non-LVC | AM7: {=IF(OR(O7:O164="zero_recoverable", "zero_exalt", "zero_other", "zero_uncertain"), "Yes","No")} -> Yes | AN7: =1 + COUNTIF($V$2:V6,"main") -> 2 | AO7: =IF($A7="","",IF($AH7=$AH8,$V8,"")) | AP7: =IF(OR($V7="relative",$V7="nominalised"),0,1) -> 1 | AQ7: =IF(AP8=0,"",COUNTIFS($AN$2:$AN8,$AN8,$AP$2:$AP8,1)) | AR7: 1 | AS7: zero_exalt | AT7: not_applicable | AU7: =IF(AND($O7="overt",LEFT($AS7,5)="zero_"),1,0) -> 0 | AV7: =IF(AND($Q7="overt",LEFT($AT7,5)="zero_"),1,0) -> 0
A8: Heike 2.7 | B8: 仰せ下されける (ōse-kudasa rekeru) | C8: he was honoured by receiving the territory of the province of Tamba, | D8: 仰せ下されける | E8: indicative | F8: action | G8: verb(complex) | H8: intransitive | I8: passive | J8: positive | K8: 1 | L8: 0 | M8: n/a | N8: 0 | O8: zero_exalt | P8: 3 | Q8: n/a | R8: n/a | S8: 1 | T8: 0 | U8: REL | V8: relative | W8: 0 | X8: 1 | Y8: io | Z8: lexical honorific+honorific aux | AA8: 0 | AB8: none | AC8: subordinate | AD8: =IF(V8<>"te","", IF(OR(AC8="",AC8<>"te"), "te_initial", "te_medial")) | AE8: ds | AF8: ss | AG8: topic-drop | AH8: no_overt_NP | AK8: =L8/K8 -> 0 | AL8: =IF(OR(G8="LVC", G8="LVC (j)", G8="LVC (inf)"), "LVC","non-LVC") -> non-LVC | AM8: {=IF(OR(O8:O165="zero_recoverable", "zero_exalt", "zero_other", "zero_uncertain"), "Yes","No")} -> Yes | AN8: =1 + COUNTIF($V$2:V7,"main") -> 2 | AO8: =IF($A8="","",IF($AH8=$AH9,$V9,"")) | AP8: =IF(OR($V8="relative",$V8="nominalised"),0,1) -> 0 | AQ8: =IF(AP9=0,"",COUNTIFS($AN$2:$AN9,$AN9,$AP$2:$AP9,1)) | AR8: =IF(AQ8=1,1,0) -> 0 | AS8: overt | AT8: n/a | AU8: =IF(AND($O8="overt",LEFT($AS8,5)="zero_"),1,0) -> 0 | AV8: =IF(AND($Q8="overt",LEFT($AT8,5)="zero_"),1,0) -> 0
A9: Heike 2.8 | B9: 折節但馬国の空きたりけるをぞ (orifushi Tamba no kuni no aki tarikeru o zo) | C9: which then happened to be unappropriated. | D9: 空きたりける | E9: indicative | F9: stative | G9: verb | H9: intransitive | I9: resultative | J9: positive | K9: 1 | L9: 1 | M9: SUB | N9: 1 | O9: overt | P9: 3 | Q9: n/a | R9: n/a | S9: 0 | T9: 0 | U9: OBJ | V9: nominalised | W9: 0 | X9: 0 | Y9: n/a | Z9: n/a | AA9: 0 | AB9: none | AC9: relative | AD9: =IF(V9<>"te","", IF(OR(AC9="",AC9<>"te"), "te_initial", "te_medial")) | AE9: ss | AF9: ds | AG9: topic-drop | AH9: contains_new | AI9: internally headed | AK9: =L9/K9 -> 1 | AL9: =IF(OR(G9="LVC", G9="LVC (j)", G9="LVC (inf)"), "LVC","non-LVC") -> non-LVC | AM9: {=IF(OR(O9:O166="zero_recoverable", "zero_exalt", "zero_other", "zero_uncertain"), "Yes","No")} -> Yes | AN9: =1 + COUNTIF($V$2:V8,"main") -> 2 | AO9: =IF($A9="","",IF($AH9=$AH10,$V10,"")) | AP9: =IF(OR($V9="relative",$V9="nominalised"),0,1) -> 0 | AQ9: =IF(AP10=0,"",COUNTIFS($AN$2:$AN10,$AN10,$AP$2:$AP10,1)) -> 2 | AR9: =IF(AQ9=1,1,0) -> 0 | AS9: zero_exalt | AT9: zero_recoverable | AU9: =IF(AND($O9="overt",LEFT($AS9,5)="zero_"),1,0) -> 1 | AV9: =IF(AND($Q9="overt",LEFT($AT9,5)="zero_"),1,0) -> 0
A10: Heike 2.9 | B10: 賜はりける (tamawari keru) | C10: As a reward he was honoured by receiving the territory of the province of Tamba, which then happened to be unappropriated. | D10: 賜はりける | E10: indicative | F10: action | G10: verb | H10: transitive | I10: active | J10: positive | K10: 1 | L10: 1 | M10: OBJ | N10: 0 | O10: zero_exalt | P10: 3 | Q10: zero_recoverable | R10: zero_recoverable | S10: 0 | T10: 0 | U10: n/a | V10: main | W10: 0 | X10: 1 | Y10: sub | Z10: lexical_humble_verb | AA10: 0 | AB10: none | AC10: nominalised | AD10: =IF(V10<>"te","", IF(OR(AC10="",AC10<>"te"), "te_initial", "te_medial")) | AE10: ds | AF10: ds | AG10: topic-drop | AH10: no_overt_NP | AK10: =L10/K10 -> 1 | AL10: =IF(OR(G10="LVC", G10="LVC (j)", G10="LVC (inf)"), "LVC","non-LVC") -> non-LVC | AM10: {=IF(OR(O10:O167="zero_recoverable", "zero_exalt", "zero_other", "zero_uncertain"), "Yes","No")} -> Yes | AN10: =1 + COUNTIF($V$2:V9,"main") -> 2 | AO10: =IF($A10="","",IF($AH10=$AH11,$V11,"")) | AP10: =IF(OR($V10="relative",$V10="nominalised"),0,1) -> 1 | AQ10: =IF(AP11=0,"",COUNTIFS($AN$2:$AN11,$AN11,$AP$2:$AP11,1)) | AR10: =IF(AQ10=1,1,0) -> 0 | AS10: overt | AT10: overt | AU10: =IF(AND($O10="overt",LEFT($AS10,5)="zero_"),1,0) -> 0 | AV10: =IF(AND($Q10="overt",LEFT($AT10,5)="zero_"),1,0) -> 0
A11: Heike 2.10 | B11: 上皇御感のあまりに内の昇殿を許さる (jōkō go-kan no amari ni uchi no shōden o yurusaru) | C11: Moreover the Emperor of his bounty graciously permitted him to attend the Court; | D11: 許さる | E11: indicative | F11: action | G11: verb | H11: transitive | I11: active | J11: positive | K11: 1 | L11: 2 | M11: S+O | N11: 1 | O11: overt | P11: 3 | Q11: overt | R11: zero_recoverable | S11: 1 | T11: 0 | U11: REL | V11: relative | W11: 1 | X11: 0 | Y11: sub | Z11: honorific_aux | AA11: 1 | AB11: none | AC11: main | AD11: =IF(V11<>"te","", IF(OR(AC11="",AC11<>"te"), "te_initial", "te_medial")) | AE11: ds | AF11: ds | AG11: topic-drop | AH11: contains_new | AI11: it's unlcear whether -re- in -yurusareru is passive or honorific | AK11: =L11/K11 -> 2 | AL11: =IF(OR(G11="LVC", G11="LVC (j)", G11="LVC (inf)"), "LVC","non-LVC") -> non-LVC | AM11: {=IF(OR(O11:O168="zero_recoverable", "zero_exalt", "zero_other", "zero_uncertain"), "Yes","No")} -> Yes | AN11: =1 + COUNTIF($V$2:V10,"main") -> 3 | AO11: =IF($A11="","",IF($AH11=$AH12,$V12,"")) -> main | AP11: =IF(OR($V11="relative",$V11="nominalised"),0,1) -> 0 | AQ11: =IF(AP12=0,"",COUNTIFS($AN$2:$AN12,$AN12,$AP$2:$AP12,1)) -> 1 | AR11: 0 | AS11: overt | AT11: overt | AU11: =IF(AND($O11="overt",LEFT($AS11,5)="zero_"),1,0) -> 0 | AV11: =IF(AND($Q11="overt",LEFT($AT11,5)="zero_"),1,0) -> 0
A12: Heike 2.11 | B12: 忠盛三十六にて初めて昇殿す (Tadamori sanjūroku nite hajimete shōden su) | C12: which Tadamori did for the first time at the age of thirty six. | D12: 昇殿す | E12: indicative | F12: motion | G12: LVC | H12: intransitive | I12: active | J12: positive | K12: 1 | L12: 1 | M12: SUB | N12: 2 | O12: overt | P12: 3 | Q12: overt | R12: n/a | S12: 0 | T12: 0 | U12: n/a | V12: main | W12: 0 | X12: 0 | Y12: n/a | Z12: n/a | AA12: 0 | AB12: none | AC12: relative | AD12: =IF(V12<>"te","", IF(OR(AC12="",AC12<>"te"), "te_initial", "te_medial")) | AE12: ds | AF12: ds | AG12: topic-continued | AH12: contains_new | AK12: =L12/K12 -> 1 | AL12: =IF(OR(G12="LVC", G12="LVC (j)", G12="LVC (inf)"), "LVC","non-LVC") -> LVC | AM12: {=IF(OR(O12:O169="zero_recoverable", "zero_exalt", "zero_other", "zero_uncertain"), "Yes","No")} -> Yes | AN12: =1 + COUNTIF($V$2:V11,"main") -> 3 | AO12: =IF($A12="","",IF($AH12=$AH13,$V13,"")) -> inf | AP12: =IF(OR($V12="relative",$V12="nominalised"),0,1) -> 1 | AQ12: =IF(AP13=0,"",COUNTIFS($AN$2:$AN13,$AN13,$AP$2:$AP13,1)) -> 1 | AR12: =IF(AQ12=1,1,0) -> 1 | AS12: overt | AT12: overt | AU12: =IF(AND($O12="overt",LEFT($AS12,5)="zero_"),1,0) -> 0 | AV12: =IF(AND($Q12="overt",LEFT($AT12,5)="zero_"),1,0) -> 0
A13: Heike 2.12 | B13: 雲の上人これを嫉み憤り (kumo no uebito kore o sonemi ikidori) | C13: the higher Courtiers were furious with jealousy | D13: 嫉み憤り | E13: indicative | F13: psych-state | G13: verb(compound) | H13: transitive | I13: active | J13: positive | K13: 1 | L13: 2 | M13: S+O | N13: 0 | O13: overt | P13: 3 | Q13: overt | R13: n/a | S13: 0 | T13: 0 | U13: n/a | V13: inf | W13: 0 | X13: 0 | Y13: n/a | Z13: n/a | AA13: 0 | AB13: none | AC13: main | AD13: =IF(V13<>"te","", IF(OR(AC13="",AC13<>"te"), "te_initial", "te_medial")) | AE13: ds | AF13: ss | AG13: topic-introduced | AH13: contains_new | AK13: =L13/K13 -> 2 | AL13: =IF(OR(G13="LVC", G13="LVC (j)", G13="LVC (inf)"), "LVC","non-LVC") -> non-LVC | AM13: {=IF(OR(O13:O170="zero_recoverable", "zero_exalt", "zero_other", "zero_uncertain"), "Yes","No")} -> Yes | AN13: =1 + COUNTIF($V$2:V12,"main") -> 4 | AO13: =IF($A13="","",IF($AH13=$AH14,$V14,"")) -> complement | AP13: =IF(OR($V13="relative",$V13="nominalised"),0,1) -> 1 | AQ13: =IF(AP14=0,"",COUNTIFS($AN$2:$AN14,$AN14,$AP$2:$AP14,1)) -> 2 | AR13: =IF(AQ13=1,1,0) -> 0 | AS13: zero_recoverable | AT13: overt | AU13: =IF(AND($O13="overt",LEFT($AS13,5)="zero_"),1,0) -> 1 | AV13: =IF(AND($Q13="overt",LEFT($AT13,5)="zero_"),1,0) -> 0
A14: Heike 2.13 | B14: 同じき年の十一月二十三日五節豊の明の節会の夜 (onajiki toshi no jūichigatsu nijūsannichi gosechi Toyo-no-akari no setchie no yo) 忠盛を闇討にせん (Tadamori o yamiuchi ni sen | C14: to assassinate him on the evening of the festival of Go-Sechi Toyo-no-akari-no-setchie, on the 23rd day of the eleventh month of the same year. | D14: 闇討にせん | E14: dynamic | F14: other | G14: LVC | H14: transitive | I14: active | J14: positive | K14: 1 | L14: 1 | M14: OBJ | N14: 1 | O14: zero_recoverable | P14: 3 | Q14: overt | R14: n/a | S14: 0 | T14: 0 | U14: n/a | V14: complement | W14: 0 | X14: 0 | Y14: n/a | Z14: n/a | AA14: 0 | AB14: quotative | AC14: inf | AD14: =IF(V14<>"te","", IF(OR(AC14="",AC14<>"te"), "te_initial", "te_medial")) | AE14: ss | AF14: ds | AG14: topic-continued | AH14: contains_new | AK14: =L14/K14 -> 1 | AL14: =IF(OR(G14="LVC", G14="LVC (j)", G14="LVC (inf)"), "LVC","non-LVC") -> LVC | AM14: {=IF(OR(O14:O171="zero_recoverable", "zero_exalt", "zero_other", "zero_uncertain"), "Yes","No")} -> Yes | AN14: =1 + COUNTIF($V$2:V13,"main") -> 4 | AO14: =IF($A14="","",IF($AH14=$AH15,$V15,"")) | AP14: =IF(OR($V14="relative",$V14="nominalised"),0,1) -> 1 | AQ14: =IF(AP15=0,"",COUNTIFS($AN$2:$AN15,$AN15,$AP$2:$AP15,1)) -> 3 | AR14: =IF(AQ14=1,1,0) -> 0 | AS14: overt | AT14: n/a | AU14: =IF(AND($O14="overt",LEFT($AS14,5)="zero_"),1,0) -> 0 | AV14: =IF(AND($Q14="overt",LEFT($AT14,5)="zero_"),1,0) -> 0
A15: Heike 2.14 | B15: とぞ議せられける (to zo giserarikeru) | C15: they plotted | D15: 議せられける | E15: indicative | F15: communication | G15: LVC | H15: intransitive | I15: passive | J15: positive | K15: 1 | L15: 1 | M15: S (Speech) | N15: 0 | O15: overt | P15: n/a | Q15: n/a | R15: n/a | S15: 0 | T15: 0 | U15: n/a | V15: main | W15: 0 | X15: 0 | Y15: n/a | Z15: n/a | AA15: 0 | AB15: none | AC15: complement | AD15: =IF(V15<>"te","", IF(OR(AC15="",AC15<>"te"), "te_initial", "te_medial")) | AE15: ds | AF15: ds | AG15: topic-drop | AH15: all given | AK15: =L15/K15 -> 1 | AL15: =IF(OR(G15="LVC", G15="LVC (j)", G15="LVC (inf)"), "LVC","non-LVC") -> LVC | AM15: {=IF(OR(O15:O172="zero_recoverable", "zero_exalt", "zero_other", "zero_uncertain"), "Yes","No")} -> Yes | AN15: =1 + COUNTIF($V$2:V14,"main") -> 4 | AO15: =IF($A15="","",IF($AH15=$AH16,$V16,"")) -> te | AP15: =IF(OR($V15="relative",$V15="nominalised"),0,1) -> 1 | AQ15: =IF(AP16=0,"",COUNTIFS($AN$2:$AN16,$AN16,$AP$2:$AP16,1)) -> 1 | AR15: 0 | AS15: overt | AT15: overt | AU15: =IF(AND($O15="overt",LEFT($AS15,5)="zero_"),1,0) -> 0 | AV15: =IF(AND($Q15="overt",LEFT($AT15,5)="zero_"),1,0) -> 0
A16: Heike 2.15 | B16: 忠盛この由を伝へ聞きて (Tadamori kono yoshi o tsutae kikite) | C16: Tadamori, on hearing of this | D16: 伝へ聞きて | E16: indicative | F16: perception | G16: verb(compound) | H16: transitive | I16: active | J16: positive | K16: 1 | L16: 2 | M16: OBJ | N16: 0 | O16: overt | P16: 3 | Q16: overt | R16: n/a | S16: 0 | T16: 0 | U16: n/a | V16: te | W16: 0 | X16: 0 | Y16: n/a | Z16: n/a | AA16: 0 | AB16: sequential | AC16: main | AD16: =IF(V16<>"te","", IF(OR(AC16="",AC16<>"te"), "te_initial", "te_medial")) -> te_initial | AE16: ds | AF16: ds | AG16: topic-shift | AH16: all given | AK16: =L16/K16 -> 2 | AL16: =IF(OR(G16="LVC", G16="LVC (j)", G16="LVC (inf)"), "LVC","non-LVC") -> non-LVC | AM16: {=IF(OR(O16:O173="zero_recoverable", "zero_exalt", "zero_other", "zero_uncertain"), "Yes","No")} -> Yes | AN16: =1 + COUNTIF($V$2:V15,"main") -> 5 | AO16: =IF($A16="","",IF($AH16=$AH17,$V17,"")) | AP16: =IF(OR($V16="relative",$V16="nominalised"),0,1) -> 1 | AQ16: =IF(AP17=0,"",COUNTIFS($AN$2:$AN17,$AN17,$AP$2:$AP17,1)) -> 2 | AR16: 1 | AS16: overt | AT16: n/a | AU16: =IF(AND($O16="overt",LEFT($AS16,5)="zero_"),1,0) -> 0 | AV16: =IF(AND($Q16="overt",LEFT($AT16,5)="zero_"),1,0) -> 0
A17: Heike 2.16 | B17: 我右弼の身にあらず (ware ubitsu no mi ni a-razu) | C17: I am not a civil official | D17: あらず | E17: indicative | F17: other | G17: copula | H17: intransitive | I17: active | J17: negative | K17: 1 | L17: 1 | M17: SUB | N17: 0 | O17: overt | P17: 1 | Q17: n/a | R17: n/a | S17: 0 | T17: 0 | U17: n/a | V17: subordinate | W17: 0 | X17: 0 | Y17: n/a | Z17: n/a | AA17: 0 | AB17: sequential | AC17: te | AD17: =IF(V17<>"te","", IF(OR(AC17="",AC17<>"te"), "te_initial", "te_medial")) | AE17: ds | AF17: ss | AG17: topic-shift | AH17: contains_new | AK17: =L17/K17 -> 1 | AL17: =IF(OR(G17="LVC", G17="LVC (j)", G17="LVC (inf)"), "LVC","non-LVC") -> non-LVC | AM17: {=IF(OR(O17:O174="zero_recoverable", "zero_exalt", "zero_other", "zero_uncertain"), "Yes","No")} -> Yes | AN17: =1 + COUNTIF($V$2:V16,"main") -> 5 | AO17: =IF($A17="","",IF($AH17=$AH18,$V18,"")) -> te | AP17: =IF(OR($V17="relative",$V17="nominalised"),0,1) -> 1 | AQ17: =IF(AP18=0,"",COUNTIFS($AN$2:$AN18,$AN18,$AP$2:$AP18,1)) -> 3 | AR17: =IF(AQ17=1,1,0) -> 0 | AS17: zero_recoverable | AT17: n/a | AU17: =IF(AND($O17="overt",LEFT($AS17,5)="zero_"),1,0) -> 1 | AV17: =IF(AND($Q17="overt",LEFT($AT17,5)="zero_"),1,0) -> 0
A18: Heike 2.17 | B18: 武勇の家に生れて (buyū no ie ni umarete) | C18: being born of a line of warriors | D18: 生れて | E18: indicative | F18: other | G18: verb | H18: intransitive | I18: active | J18: positive | K18: 1 | L18: 1 | M18: SUB | N18: 1 | O18: zero_recoverable | P18: 1 | Q18: n/a | R18: n/a | S18: 0 | T18: 0 | U18: n/a | V18: te | W18: 0 | X18: 0 | Y18: n/a | Z18: n/a | AA18: 0 | AB18: sequential | AC18: subordinate | AD18: te_medial | AE18: ss | AF18: ss | AG18: topic-drop | AH18: contains_new | AK18: =L18/K18 -> 1 | AL18: =IF(OR(G18="LVC", G18="LVC (j)", G18="LVC (inf)"), "LVC","non-LVC") -> non-LVC | AM18: {=IF(OR(O18:O175="zero_recoverable", "zero_exalt", "zero_other", "zero_uncertain"), "Yes","No")} -> Yes | AN18: =1 + COUNTIF($V$2:V17,"main") -> 5 | AO18: =IF($A18="","",IF($AH18=$AH19,$V19,"")) -> relative | AP18: =IF(OR($V18="relative",$V18="nominalised"),0,1) -> 1 | AQ18: =IF(AP19=0,"",COUNTIFS($AN$2:$AN19,$AN19,$AP$2:$AP19,1)) | AR18: =IF(AQ18=1,1,0) -> 0 | AS18: zero_recoverable | AT18: n/a | AU18: =IF(AND($O18="overt",LEFT($AS18,5)="zero_"),1,0) -> 0 | AV18: =IF(AND($Q18="overt",LEFT($AT18,5)="zero_"),1,0) -> 0
A19: Heike 2.18 | B19: 今不慮の恥に遇はん (ima furyo no haji ni awan) | C19: for myself and my house at this unexpected shame | D19: 遇はん | E19: epistemic | F19: other | G19: verb | H19: intransitive | I19: active | J19: positive | K19: 1 | L19: 1 | M19: IO | N19: 1 | O19: zero_recoverable | P19: n/a | Q19: n/a | R19: overt | S19: 0 | T19: 1 | U19: n/a | V19: relative | W19: 0 | X19: 0 | Y19: n/a | Z19: n/a | AA19: 0 | AB19: none | AC19: te | AD19: =IF(V19<>"te","", IF(OR(AC19="",AC19<>"te"), "te_initial", "te_medial")) | AE19: ss | AF19: ds | AG19: topic-drop | AH19: contains_new | AK19: =L19/K19 -> 1 | AL19: =IF(OR(G19="LVC", G19="LVC (j)", G19="LVC (inf)"), "LVC","non-LVC") -> non-LVC | AM19: {=IF(OR(O19:O176="zero_recoverable", "zero_exalt", "zero_other", "zero_uncertain"), "Yes","No")} -> Yes | AN19: =1 + COUNTIF($V$2:V18,"main") -> 5 | AO19: =IF($A19="","",IF($AH19=$AH20,$V20,"")) -> main | AP19: =IF(OR($V19="relative",$V19="nominalised"),0,1) -> 0 | AQ19: =IF(AP20=0,"",COUNTIFS($AN$2:$AN20,$AN20,$AP$2:$AP20,1)) -> 4 | AR19: =IF(AQ19=1,1,0) -> 0 | AS19: overt | AT19: n/a | AU19: =IF(AND($O19="overt",LEFT($AS19,5)="zero_"),1,0) -> 0 | AV19: =IF(AND($Q19="overt",LEFT($AT19,5)="zero_"),1,0) -> 0
A20: Heike 2.19 | B20: 事家の為身の為心憂かるべし (koto ie no tame mi no tame kokoroukarubeshi) | C20: I am troubled in my heart | D20: 憂かるべし | E20: epistemic | F20: psych-state | G20: adjectival predicate | H20: intransitive | I20: active | J20: positive | K20: 1 | L20: 1 | M20: SUB | N20: 1 | O20: overt | P20: 3 | Q20: n/a | R20: n/a | S20: 0 | T20: 0 | U20: n/a | V20: main | W20: 0 | X20: 0 | Y20: n/a | Z20: n/a | AA20: 0 | AB20: none | AC20: relative | AD20: =IF(V20<>"te","", IF(OR(AC20="",AC20<>"te"), "te_initial", "te_medial")) | AE20: ds | AF20: 0 | AG20: topic-drop | AH20: contains_new | AK20: =L20/K20 -> 1 | AL20: =IF(OR(G20="LVC", G20="LVC (j)", G20="LVC (inf)"), "LVC","non-LVC") -> non-LVC | AM20: {=IF(OR(O20:O177="zero_recoverable", "zero_exalt", "zero_other", "zero_uncertain"), "Yes","No")} -> Yes | AN20: =1 + COUNTIF($V$2:V19,"main") -> 5 | AO20: =IF($A20="","",IF($AH20=$AH21,$V21,"")) | AP20: =IF(OR($V20="relative",$V20="nominalised"),0,1) -> 1 | AQ20: =IF(AP21=0,"",COUNTIFS($AN$2:$AN21,$AN21,$AP$2:$AP21,1)) -> 1 | AR20: 0 | AU20: =IF(AND($O20="overt",LEFT($AS20,5)="zero_"),1,0) -> 0 | AV20: =IF(AND($Q20="overt",LEFT($AT20,5)="zero_"),1,0) -> 0
A21: Heike 2.20 | B21: 詮ずるところ (senzuru tokoro) | C21: finally, as for what is to be done | D21: 詮ずる | E21: indicative | F21: other | Q21: n/a | R21: n/a | AC21: main | AD21: =IF(V21<>"te","", IF(OR(AC21="",AC21<>"te"), "te_initial", "te_medial")) | AF21: ss | AL21: =IF(OR(G21="LVC", G21="LVC (j)", G21="LVC (inf)"), "LVC","non-LVC") -> non-LVC | AM21: {=IF(OR(O21:O178="zero_recoverable", "zero_exalt", "zero_other", "zero_uncertain"), "Yes","No")} -> Yes | AN21: =1 + COUNTIF($V$2:V20,"main") -> 6 | AO21: =IF($A21="","",IF($AH21=$AH22,$V22,"")) | AP21: =IF(OR($V21="relative",$V21="nominalised"),0,1) -> 1 | AQ21: =IF(AP22=0,"",COUNTIFS($AN$2:$AN22,$AN22,$AP$2:$AP22,1)) -> 2 | AR21: =IF(AQ21=1,1,0) -> 0 | AS21: zero_recoverable | AT21: overt | AU21: =IF(AND($O21="overt",LEFT($AS21,5)="zero_"),1,0) -> 0 | AV21: =IF(AND($Q21="overt",LEFT($AT21,5)="zero_"),1,0) -> 0
A22: Heike 2.21 | B22: 身を全うして (mi o mattō shite) | C22: with all your might | D22: 全うして | E22: indicative | F22: other | G22: LVC | H22: transitive | I22: active | J22: positive | K22: 1 | L22: 1 | M22: OBJ | N22: 0 | O22: zero_recoverable | P22: 1 | Q22: overt | R22: n/a | S22: 0 | T22: 0 | U22: n/a | V22: te | W22: 0 | X22: 0 | Y22: n/a | Z22: n/a | AA22: 0 | AB22: sequential | AC22: 0 | AD22: te_medial | AE22: ss | AF22: ss | AG22: topic-drop | AH22: contains_new | AK22: =L22/K22 -> 1 | AL22: =IF(OR(G22="LVC", G22="LVC (j)", G22="LVC (inf)"), "LVC","non-LVC") -> LVC | AM22: {=IF(OR(O22:O179="zero_recoverable", "zero_exalt", "zero_other", "zero_uncertain"), "Yes","No")} -> Yes | AN22: =1 + COUNTIF($V$2:V21,"main") -> 6 | AO22: =IF($A22="","",IF($AH22=$AH23,$V23,"")) -> complement | AP22: =IF(OR($V22="relative",$V22="nominalised"),0,1) -> 1 | AQ22: =IF(AP23=0,"",COUNTIFS($AN$2:$AN23,$AN23,$AP$2:$AP23,1)) -> 3 | AR22: =IF(AQ22=1,1,0) -> 0 | AS22: zero_exalt | AT22: n/a | AU22: =IF(AND($O22="overt",LEFT($AS22,5)="zero_"),1,0) -> 0 | AV22: =IF(AND($Q22="overt",LEFT($AT22,5)="zero_"),1,0) -> 0
A23: Heike 2.22 | B23: 君に仕へ奉れ | C23: kimi ni tsukae tatematsure | D23: 仕へ奉れ | E23: imperative | F23: action | G23: verb | H23: intransitive | I23: active | J23: positive | K23: 1 | L23: 1 | M23: IO | N23: 0 | O23: zero_exalt | P23: 1 | Q23: n/a | R23: overt | S23: 0 | T23: 0 | U23: n/a | V23: complement | W23: 1 | X23: 1 | Y23: sub | Z23: lexical_humble_verb | AA23: 0 | AB23: none | AC23: te | AD23: =IF(V23<>"te","", IF(OR(AC23="",AC23<>"te"), "te_initial", "te_medial")) | AE23: ss | AF23: ds | AG23: topic-drop | AH23: contains_new | AK23: =L23/K23 -> 1 | AL23: =IF(OR(G23="LVC", G23="LVC (j)", G23="LVC (inf)"), "LVC","non-LVC") -> non-LVC | AM23: {=IF(OR(O23:O180="zero_recoverable", "zero_exalt", "zero_other", "zero_uncertain"), "Yes","No")} -> Yes | AN23: =1 + COUNTIF($V$2:V22,"main") -> 6 | AO23: =IF($A23="","",IF($AH23=$AH24,$V24,"")) -> main | AP23: =IF(OR($V23="relative",$V23="nominalised"),0,1) -> 1 | AQ23: =IF(AP24=0,"",COUNTIFS($AN$2:$AN24,$AN24,$AP$2:$AP24,1)) -> 4 | AR23: =IF(AQ23=1,1,0) -> 0 | AS23: overt | AT23: n/a | AU23: =IF(AND($O23="overt",LEFT($AS23,5)="zero_"),1,0) -> 0 | AV23: =IF(AND($Q23="overt",LEFT($AT23,5)="zero_"),1,0) -> 0
A24: Heike 2.23 | B24: といふ本文あり (to iu honbun ari) | C24: so goes the original passage | D24: あり | E24: indicative | F24: stative | G24: existential verb | H24: intransitive | I24: active | J24: positive | K24: 1 | L24: 1 | M24: SUB | N24: 1 | O24: overt | P24: 3 | Q24: n/a | R24: n/a | S24: 0 | T24: 0 | U24: n/a | V24: main | W24: 0 | X24: 0 | Y24: n/a | Z24: n/a | AA24: 0 | AB24: none | AC24: complement | AD24: =IF(V24<>"te","", IF(OR(AC24="",AC24<>"te"), "te_initial", "te_medial")) | AE24: ds | AF24: ss | AG24: topic-drop | AH24: contains_new | AI24: frame predicate | AK24: =L24/K24 -> 1 | AL24: =IF(OR(G24="LVC", G24="LVC (j)", G24="LVC (inf)"), "LVC","non-LVC") -> non-LVC | AM24: {=IF(OR(O24:O181="zero_recoverable", "zero_exalt", "zero_other", "zero_uncertain"), "Yes","No")} -> Yes | AN24: =1 + COUNTIF($V$2:V23,"main") -> 6 | AO24: =IF($A24="","",IF($AH24=$AH25,$V25,"")) -> inf | AP24: =IF(OR($V24="relative",$V24="nominalised"),0,1) -> 1 | AQ24: =IF(AP25=0,"",COUNTIFS($AN$2:$AN25,$AN25,$AP$2:$AP25,1)) -> 1 | AR24: 0 | AS24: zero_recoverable | AT24: overt | AU24: =IF(AND($O24="overt",LEFT($AS24,5)="zero_"),1,0) -> 1 | AV24: =IF(AND($Q24="overt",LEFT($AT24,5)="zero_"),1,0) -> 0
A25: Heike 2.24 | B25: 参内の初めより大なる鞘巻を用意し (sannai no hajime yori ō-naru sayamaki o yōi shi) | C25: Before entering the Court he provided himself with a long dirk | D25: 用意し | E25: indicative | F25: other | G25: LVC | H25: transitive | I25: active | J25: positive | K25: 1 | L25: 1 | M25: OBJ | N25: 1 | O25: zero_recoverable | P25: 3 | Q25: overt | R25: n/a | S25: 0 | T25: 0 | U25: n/a | V25: inf | W25: 0 | X25: 0 | Y25: n/a | Z25: n/a | AA25: 0 | AB25: none | AC25: main | AD25: =IF(V25<>"te","", IF(OR(AC25="",AC25<>"te"), "te_initial", "te_medial")) | AE25: ss | AF25: ss | AG25: topic-drop | AH25: contains_new | AK25: =L25/K25 -> 1 | AL25: =IF(OR(G25="LVC", G25="LVC (j)", G25="LVC (inf)"), "LVC","non-LVC") -> LVC | AM25: {=IF(OR(O25:O182="zero_recoverable", "zero_exalt", "zero_other", "zero_uncertain"), "Yes","No")} -> Yes | AN25: =1 + COUNTIF($V$2:V24,"main") -> 7 | AO25: =IF($A25="","",IF($AH25=$AH26,$V26,"")) -> inf | AP25: =IF(OR($V25="relative",$V25="nominalised"),0,1) -> 1 | AQ25: =IF(AP26=0,"",COUNTIFS($AN$2:$AN26,$AN26,$AP$2:$AP26,1)) -> 2 | AR25: 1 | AS25: zero_recoverable | AT25: zero_recoverable | AU25: =IF(AND($O25="overt",LEFT($AS25,5)="zero_"),1,0) -> 0 | AV25: =IF(AND($Q25="overt",LEFT($AT25,5)="zero_"),1,0) -> 1
A26: Heike 2.25 | B26: 束帯の下にしどけなげに差し (sokutai no shita ni shidokenage ni sashi) | C26: which he girt on under his long court dress | D26: 差し | E26: indicative | F26: other | G26: verb | H26: transitive | I26: active | J26: positive | K26: 1 | L26: 1 | M26: IO | N26: 1 | O26: zero_recoverable | P26: 3 | Q26: zero_recoverable | R26: overt | S26: 0 | T26: 0 | U26: n/a | V26: inf | W26: 0 | X26: 0 | Y26: n/a | Z26: n/a | AA26: 0 | AB26: none | AC26: inf | AD26: =IF(V26<>"te","", IF(OR(AC26="",AC26<>"te"), "te_initial", "te_medial")) | AE26: ss | AF26: ss | AG26: topic-drop | AH26: contains_new | AK26: =L26/K26 -> 1 | AL26: =IF(OR(G26="LVC", G26="LVC (j)", G26="LVC (inf)"), "LVC","non-LVC") -> non-LVC | AM26: {=IF(OR(O26:O183="zero_recoverable", "zero_exalt", "zero_other", "zero_uncertain"), "Yes","No")} -> Yes | AN26: =1 + COUNTIF($V$2:V25,"main") -> 7 | AO26: =IF($A26="","",IF($AH26=$AH27,$V27,"")) -> te | AP26: =IF(OR($V26="relative",$V26="nominalised"),0,1) -> 1 | AQ26: =IF(AP27=0,"",COUNTIFS($AN$2:$AN27,$AN27,$AP$2:$AP27,1)) -> 3 | AR26: =IF(AQ26=1,1,0) -> 0 | AS26: zero_recoverable | AT26: n/a | AU26: =IF(AND($O26="overt",LEFT($AS26,5)="zero_"),1,0) -> 0 | AV26: =IF(AND($Q26="overt",LEFT($AT26,5)="zero_"),1,0) -> 0
A27: Heike 2.26 | B27: 火の仄暗き方に向かつて (hi no hokuraki kata ni mukatte) | C27: and turning aside to a dimly lit place | D27: 向かつて | E27: indicative | F27: other | G27: verb | H27: intransitive | I27: active | J27: positive | K27: 1 | L27: 1 | M27: IO | N27: 1 | O27: zero_recoverable | P27: 3 | Q27: n/a | R27: overt | S27: 0 | T27: 0 | U27: n/a | V27: te | W27: 0 | X27: 0 | Y27: n/a | Z27: n/a | AA27: 0 | AB27: sequential | AC27: inf | AD27: te_medial | AE27: ss | AF27: ss | AG27: topic-drop | AH27: contains_new | AK27: =L27/K27 -> 1 | AL27: =IF(OR(G27="LVC", G27="LVC (j)", G27="LVC (inf)"), "LVC","non-LVC") -> non-LVC | AM27: {=IF(OR(O27:O184="zero_recoverable", "zero_exalt", "zero_other", "zero_uncertain"), "Yes","No")} -> Yes | AN27: =1 + COUNTIF($V$2:V26,"main") -> 7 | AO27: =IF($A27="","",IF($AH27=$AH28,$V28,"")) | AP27: =IF(OR($V27="relative",$V27="nominalised"),0,1) -> 1 | AQ27: =IF(AP28=0,"",COUNTIFS($AN$2:$AN28,$AN28,$AP$2:$AP28,1)) -> 4 | AR27: =IF(AQ27=1,1,0) -> 0 | AS27: zero_recoverable | AT27: overt | AU27: =IF(AND($O27="overt",LEFT($AS27,5)="zero_"),1,0) -> 0 | AV27: =IF(AND($Q27="overt",LEFT($AT27,5)="zero_"),1,0) -> 0
A28: Heike 2.27 | B28: やはらこの刀を抜き出でて (yahara kono katana o nuki-idete) | C28: slowly drew the blade | D28: 抜き出でて | E28: indicative | F28: motion | G28: verb(compound) | H28: transitive | I28: active | J28: positive | K28: 1 | L28: 1 | M28: OBJ | N28: 0 | O28: zero_recoverable | P28: 3 | Q28: overt | R28: n/a | S28: 0 | T28: 0 | U28: n/a | V28: te | W28: 0 | X28: 0 | Y28: n/a | Z28: n/a | AA28: 0 | AB28: sequential | AC28: te | AD28: =IF(V28<>"te","", IF(OR(AC28="",AC28<>"te"), "te_initial", "te_medial")) -> te_medial | AE28: ss | AF28: ss | AG28: topic-drop | AH28: all given | AI28: "kono katana" refers to the "sayamaki", so all given | AK28: =L28/K28 -> 1 | AL28: =IF(OR(G28="LVC", G28="LVC (j)", G28="LVC (inf)"), "LVC","non-LVC") -> non-LVC | AM28: {=IF(OR(O28:O185="zero_recoverable", "zero_exalt", "zero_other", "zero_uncertain"), "Yes","No")} -> Yes | AN28: =1 + COUNTIF($V$2:V27,"main") -> 7 | AO28: =IF($A28="","",IF($AH28=$AH29,$V29,"")) | AP28: =IF(OR($V28="relative",$V28="nominalised"),0,1) -> 1 | AQ28: =IF(AP29=0,"",COUNTIFS($AN$2:$AN29,$AN29,$AP$2:$AP29,1)) -> 5 | AR28: =IF(AQ28=1,1,0) -> 0 | AS28: zero_exalt | AT28: zero_recoverable | AU28: =IF(AND($O28="overt",LEFT($AS28,5)="zero_"),1,0) -> 0 | AV28: =IF(AND($Q28="overt",LEFT($AT28,5)="zero_"),1,0) -> 1
A29: Heike 2.28 | B29: 鬢に引き当てられたりけるが (kami ni hiki-ate raretarikeru ga) | C29: and passed it through the hair of his head | D29: 引き当てられたりける | E29: indicative | F29: motion | G29: verb | H29: transitive | I29: active | J29: positive | K29: 1 | L29: 1 | M29: IO | N29: 0 | O29: zero_exalt | P29: 3 | Q29: zero_recoverable | R29: overt | S29: 0 | T29: 0 | U29: n/a | V29: subordinate | W29: 0 | X29: 1 | Y29: sub | Z29: honorific_aux | AA29: 0 | AB29: conjunctive | AC29: te | AD29: =IF(V29<>"te","", IF(OR(AC29="",AC29<>"te"), "te_initial", "te_medial")) | AE29: ss | AF29: ds | AG29: topic-drop | AH29: contains_new | AI29: should the -to part be considered a clausal subject? | AK29: =L29/K29 -> 1 | AL29: =IF(OR(G29="LVC", G29="LVC (j)", G29="LVC (inf)"), "LVC","non-LVC") -> non-LVC | AM29: {=IF(OR(O29:O186="zero_recoverable", "zero_exalt", "zero_other", "zero_uncertain"), "Yes","No")} -> Yes | AN29: =1 + COUNTIF($V$2:V28,"main") -> 7 | AO29: =IF($A29="","",IF($AH29=$AH30,$V30,"")) | AP29: =IF(OR($V29="relative",$V29="nominalised"),0,1) -> 1 | AQ29: =IF(AP30=0,"",COUNTIFS($AN$2:$AN30,$AN30,$AP$2:$AP30,1)) | AR29: =IF(AQ29=1,1,0) -> 0 | AS29: zero_recoverable | AT29: n/a | AU29: =IF(AND($O29="overt",LEFT($AS29,5)="zero_"),1,0) -> 0 | AV29: =IF(AND($Q29="overt",LEFT($AT29,5)="zero_"),1,0) -> 0
A30: Heike 2.29 | B30: 余所よりは氷などのやうにぞ見えたりける (yoso yori wa kōri nado no yō ni zo mieta rikeru) | C30: so that it gleamed afar off with an icy sheen | D30: 見えたりける | E30: indicative | F30: perception | G30: verb | H30: intransitive | I30: resultative | J30: positive | K30: 1 | L30: 0 | M30: n/a | N30: 2 | O30: zero_recoverable | P30: 3 | Q30: n/a | R30: n/a | S30: 0 | T30: 0 | U30: n/a | V30: relative | W30: 0 | X30: 0 | Y30: n/a | Z30: n/a | AA30: 0 | AB30: none | AC30: subordinate | AD30: =IF(V30<>"te","", IF(OR(AC30="",AC30<>"te"), "te_initial", "te_medial")) | AE30: ds | AF30: ss | AG30: topic-drop | AH30: no_overt_NP | AK30: =L30/K30 -> 0 | AL30: =IF(OR(G30="LVC", G30="LVC (j)", G30="LVC (inf)"), "LVC","non-LVC") -> non-LVC | AM30: {=IF(OR(O30:O187="zero_recoverable", "zero_exalt", "zero_other", "zero_uncertain"), "Yes","No")} -> Yes | AN30: =1 + COUNTIF($V$2:V29,"main") -> 7 | AO30: =IF($A30="","",IF($AH30=$AH31,$V31,"")) | AP30: =IF(OR($V30="relative",$V30="nominalised"),0,1) -> 0 | AQ30: =IF(AP31=0,"",COUNTIFS($AN$2:$AN31,$AN31,$AP$2:$AP31,1)) -> 6 | AR30: =IF(AQ30=1,1,0) -> 0 | AS30: zero_recoverable | AT30: overt | AU30: =IF(AND($O30="overt",LEFT($AS30,5)="zero_"),1,0) -> 0 | AV30: =IF(AND($Q30="overt",LEFT($AT30,5)="zero_"),1,0) -> 0
A31: Heike 2.30 | B31: 諸人目を澄ましけり (morobito me o sumashikeri) | C31: causing all to stare open-eyed | D31: 澄ましけり | E31: indicative | F31: other | G31: verb | H31: transitive | I31: active | J31: positive | K31: 1 | L31: 2 | M31: O+IO | N31: 0 | O31: zero_recoverable | P31: 3 | Q31: overt | R31: overt | S31: 0 | T31: 0 | U31: n/a | V31: main | W31: 0 | X31: 0 | Y31: n/a | Z31: n/a | AA31: 0 | AB31: none | AC31: relative | AD31: =IF(V31<>"te","", IF(OR(AC31="",AC31<>"te"), "te_initial", "te_medial")) | AE31: ss | AF31: ds | AG31: topic-drop | AH31: contains_new | AK31: =L31/K31 -> 2 | AL31: =IF(OR(G31="LVC", G31="LVC (j)", G31="LVC (inf)"), "LVC","non-LVC") -> non-LVC | AM31: {=IF(OR(O31:O188="zero_recoverable", "zero_exalt", "zero_other", "zero_uncertain"), "Yes","No")} -> Yes | AN31: =1 + COUNTIF($V$2:V30,"main") -> 7 | AO31: =IF($A31="","",IF($AH31=$AH32,$V32,"")) -> relative | AP31: =IF(OR($V31="relative",$V31="nominalised"),0,1) -> 1 | AQ31: =IF(AP32=0,"",COUNTIFS($AN$2:$AN32,$AN32,$AP$2:$AP32,1)) | AR31: 1 | AS31: overt | AT31: n/a | AU31: =IF(AND($O31="overt",LEFT($AS31,5)="zero_"),1,0) -> 0 | AV31: =IF(AND($Q31="overt",LEFT($AT31,5)="zero_"),1,0) -> 0
A32: Heike 2.31 | B32: また忠盛の郎等元は一門たりし( mata Tadamori no rōtō moto wa ichimon tarishi) | C32: Moreover a retainer of Tadamori ... | D32: たりし | E32: indicative | F32: other | G32: copula | H32: intransitive | I32: active | J32: positive | K32: 1 | L32: 1 | M32: SUB | N32: 1 | O32: overt | P32: 3 | Q32: n/a | R32: n/a | S32: 0 | T32: 0 | U32: REL | V32: relative | W32: 0 | X32: 0 | Y32: n/a | Z32: n/a | AA32: 0 | AB32: conjunctive | AC32: main | AD32: =IF(V32<>"te","", IF(OR(AC32="",AC32<>"te"), "te_initial", "te_medial")) | AE32: ds | AF32: ss | AG32: topic-introduced | AH32: contains_new | AK32: =L32/K32 -> 1 | AL32: =IF(OR(G32="LVC", G32="LVC (j)", G32="LVC (inf)"), "LVC","non-LVC") -> non-LVC | AM32: {=IF(OR(O32:O189="zero_recoverable", "zero_exalt", "zero_other", "zero_uncertain"), "Yes","No")} -> Yes | AN32: =1 + COUNTIF($V$2:V31,"main") -> 8 | AO32: =IF($A32="","",IF($AH32=$AH33,$V33,"")) -> main | AP32: =IF(OR($V32="relative",$V32="nominalised"),0,1) -> 0 | AQ32: =IF(AP33=0,"",COUNTIFS($AN$2:$AN33,$AN33,$AP$2:$AP33,1)) -> 1 | AR32: 0 | AS32: overt | AT32: n/a | AU32: =IF(AND($O32="overt",LEFT($AS32,5)="zero_"),1,0) -> 0 | AV32: =IF(AND($Q32="overt",LEFT($AT32,5)="zero_"),1,0) -> 0
A33: Heike 2.32 | B33: 木工助平貞光が孫新四郎太夫家房が子に左兵衛尉家貞といふ者あり (Moku no suke Sadamitsu ga mago Shinshirō Tayū Iefusa ga ko ni Sahyōe no jō Iesada to iu mono ari) | C33: there was one named Sahyoe-no-jo Iesada | D33: あり | E33: indicative | F33: other | G33: existential verb | H33: intransitive | I33: active | J33: positive | K33: 1 | L33: 1 | M33: SUB | N33: 2 | O33: overt | P33: 3 | Q33: n/a | R33: n/a | S33: 0 | T33: 0 | U33: n/a | V33: main | W33: 0 | X33: 0 | Y33: n/a | Z33: n/a | AA33: 0 | AB33: none | AC33: relative | AD33: =IF(V33<>"te","", IF(OR(AC33="",AC33<>"te"), "te_initial", "te_medial")) | AE33: ss | AF33: ss | AG33: topic-introduced | AH33: contains_new | AI33: frame predicate | AK33: =L33/K33 -> 1 | AL33: =IF(OR(G33="LVC", G33="LVC (j)", G33="LVC (inf)"), "LVC","non-LVC") -> non-LVC | AM33: {=IF(OR(O33:O190="zero_recoverable", "zero_exalt", "zero_other", "zero_uncertain"), "Yes","No")} -> Yes | AN33: =1 + COUNTIF($V$2:V32,"main") -> 8 | AO33: =IF($A33="","",IF($AH33=$AH34,$V34,"")) -> inf | AP33: =IF(OR($V33="relative",$V33="nominalised"),0,1) -> 1 | AQ33: =IF(AP34=0,"",COUNTIFS($AN$2:$AN34,$AN34,$AP$2:$AP34,1)) -> 1 | AR33: =IF(AQ33=1,1,0) -> 1 | AS33: zero_recoverable | AT33: overt | AU33: =IF(AND($O33="overt",LEFT($AS33,5)="zero_"),1,0) -> 1 | AV33: =IF(AND($Q33="overt",LEFT($AT33,5)="zero_"),1,0) -> 0
A34: Heike 2.33 | B34: 薄青の狩衣の下に萌黄威の腹巻を着 (usuao no kariginu no shita ni moegi-odoshi no haramaki o ki) | C34: wearing a body armour laced with bright green under a light green "kariginu" | D34: 着 | E34: indicative | F34: other | G34: verb | H34: transitive | I34: active | J34: positive | K34: 1 | L34: 1 | M34: OBJ | N34: 1 | O34: zero_recoverable | P34: 3 | Q34: overt | R34: n/a | S34: 0 | T34: 0 | U34: n/a | V34: inf | W34: 0 | X34: 0 | Y34: n/a | Z34: n/a | AA34: 0 | AB34: none | AC34: main | AD34: =IF(V34<>"te","", IF(OR(AC34="",AC34<>"te"), "te_initial", "te_medial")) | AE34: ss | AF34: ss | AG34: topic-drop | AH34: contains_new | AK34: =L34/K34 -> 1 | AL34: =IF(OR(G34="LVC", G34="LVC (j)", G34="LVC (inf)"), "LVC","non-LVC") -> non-LVC | AM34: {=IF(OR(O34:O191="zero_recoverable", "zero_exalt", "zero_other", "zero_uncertain"), "Yes","No")} -> Yes | AN34: =1 + COUNTIF($V$2:V33,"main") -> 9 | AO34: =IF($A34="","",IF($AH34=$AH35,$V35,"")) -> relative | AP34: =IF(OR($V34="relative",$V34="nominalised"),0,1) -> 1 | AQ34: =IF(AP35=0,"",COUNTIFS($AN$2:$AN35,$AN35,$AP$2:$AP35,1)) | AR34: =IF(AQ34=1,1,0) -> 0 | AS34: zero_recoverable | AT34: overt | AU34: =IF(AND($O34="overt",LEFT($AS34,5)="zero_"),1,0) -> 0 | AV34: =IF(AND($Q34="overt",LEFT($AT34,5)="zero_"),1,0) -> 0
A35: Heike 2.34 | B35: 柄弦袋付けたる ezurubukuro tsuketaru | C35: with a bowstring bag attached | D35: 付けたる | E35: indicative | F35: other | G35: verb | H35: transitive | I35: active | J35: positive | K35: 1 | L35: 1 | M35: OBJ | N35: 0 | O35: zero_recoverable | P35: 3 | Q35: overt | R35: n/a | S35: 1 | T35: 0 | U35: REL | V35: relative | W35: 0 | X35: 0 | Y35: n/a | Z35: n/a | AA35: 0 | AB35: none | AC35: inf | AD35: =IF(V35<>"te","", IF(OR(AC35="",AC35<>"te"), "te_initial", "te_medial")) | AE35: ss | AF35: ss | AG35: topic-drop | AH35: contains_new | AK35: =L35/K35 -> 1 | AL35: =IF(OR(G35="LVC", G35="LVC (j)", G35="LVC (inf)"), "LVC","non-LVC") -> non-LVC | AM35: {=IF(OR(O35:O192="zero_recoverable", "zero_exalt", "zero_other", "zero_uncertain"), "Yes","No")} -> Yes | AN35: =1 + COUNTIF($V$2:V34,"main") -> 9 | AO35: =IF($A35="","",IF($AH35=$AH36,$V36,"")) -> te | AP35: =IF(OR($V35="relative",$V35="nominalised"),0,1) -> 0 | AQ35: =IF(AP36=0,"",COUNTIFS($AN$2:$AN36,$AN36,$AP$2:$AP36,1)) -> 2 | AR35: =IF(AQ35=1,1,0) -> 0 | AS35: zero_recoverable | AT35: overt | AU35: =IF(AND($O35="overt",LEFT($AS35,5)="zero_"),1,0) -> 0 | AV35: =IF(AND($Q35="overt",LEFT($AT35,5)="zero_"),1,0) -> 0
A36: Heike 2.35 | B36: 太刀脇挟んで (tachi wakihasande) | C36: and carrying under his arm a "tachi" | D36: 挟んで | E36: indicative | F36: other | G36: verb | H36: transitive | I36: active | J36: positive | K36: 1 | L36: 2 | M36: O+IO | N36: 0 | O36: zero_recoverable | P36: 3 | Q36: overt | R36: overt | S36: 0 | T36: 0 | U36: n/a | V36: te | W36: 0 | X36: 0 | Y36: n/a | Z36: n/a | AA36: 0 | AB36: none | AC36: relative | AD36: te_medial | AE36: ss | AF36: ss | AG36: topic-drop | AH36: contains_new | AK36: =L36/K36 -> 2 | AL36: =IF(OR(G36="LVC", G36="LVC (j)", G36="LVC (inf)"), "LVC","non-LVC") -> non-LVC | AM36: {=IF(OR(O36:O193="zero_recoverable", "zero_exalt", "zero_other", "zero_uncertain"), "Yes","No")} -> Yes | AN36: =1 + COUNTIF($V$2:V35,"main") -> 9 | AO36: =IF($A36="","",IF($AH36=$AH37,$V37,"")) | AP36: =IF(OR($V36="relative",$V36="nominalised"),0,1) -> 1 | AQ36: =IF(AP37=0,"",COUNTIFS($AN$2:$AN37,$AN37,$AP$2:$AP37,1)) -> 3 | AR36: =IF(AQ36=1,1,0) -> 0 | AS36: zero_recoverable | AT36: n/a | AU36: =IF(AND($O36="overt",LEFT($AS36,5)="zero_"),1,0) -> 0 | AV36: =IF(AND($Q36="overt",LEFT($AT36,5)="zero_"),1,0) -> 0
A37: Heike 2.36 | B37: 殿上の小庭に畏つてぞ候ひける (tenjō no koniwa ni kashikomatte zo soroikyeru) | C37: was waiting in the "koniwa," the small court by the Seiryoden | D37: 畏つて候ひける | E37: indicative | F37: other | G37: verb(complex) | H37: intransitive | I37: active | J37: positive | K37: 1 | L37: 0 | M37: n/a | N37: 1 | O37: zero_recoverable | P37: 3 | Q37: n/a | R37: n/a | S37: 0 | T37: 0 | U37: n/a | V37: main | W37: 0 | X37: 1 | Y37: sub | Z37: lexical_humble_verb | AA37: 0 | AB37: none | AC37: te | AD37: =IF(V37<>"te","", IF(OR(AC37="",AC37<>"te"), "te_initial", "te_medial")) | AE37: ss | AF37: ds | AG37: topic-drop | AH37: no_overt_NP | AK37: =L37/K37 -> 0 | AL37: =IF(OR(G37="LVC", G37="LVC (j)", G37="LVC (inf)"), "LVC","non-LVC") -> non-LVC | AM37: {=IF(OR(O37:O194="zero_recoverable", "zero_exalt", "zero_other", "zero_uncertain"), "Yes","No")} -> Yes | AN37: =1 + COUNTIF($V$2:V36,"main") -> 9 | AO37: =IF($A37="","",IF($AH37=$AH38,$V38,"")) | AP37: =IF(OR($V37="relative",$V37="nominalised"),0,1) -> 1 | AQ37: =IF(AP38=0,"",COUNTIFS($AN$2:$AN38,$AN38,$AP$2:$AP38,1)) -> 1 | AR37: 0 | AS37: overt | AT37: overt | AU37: =IF(AND($O37="overt",LEFT($AS37,5)="zero_"),1,0) -> 0 | AV37: =IF(AND($Q37="overt",LEFT($AT37,5)="zero_"),1,0) -> 0
A38: Heike 2.37 | B38: 貫首以下怪しみをなして (kanshu ika ayashimi o nashite) | C38: Now the Kurando-no-to and others, thinking it strange, | D38: なして | E38: indicative | F38: other | G38: LVC (inf) | H38: transitive | I38: active | J38: negative | K38: 1 | L38: 2 | M38: S+O | N38: 0 | O38: overt | P38: 3 | Q38: overt | R38: n/a | S38: 0 | T38: 0 | U38: n/a | V38: te | W38: 0 | X38: 0 | Y38: n/a | Z38: n/a | AA38: 0 | AB38: sequential | AC38: main | AD38: =IF(V38<>"te","", IF(OR(AC38="",AC38<>"te"), "te_initial", "te_medial")) -> te_initial | AE38: ds | AF38: ss | AG38: topic-shift | AH38: contains_new | AK38: =L38/K38 -> 2 | AL38: =IF(OR(G38="LVC", G38="LVC (j)", G38="LVC (inf)"), "LVC","non-LVC") -> LVC | AM38: {=IF(OR(O38:O195="zero_recoverable", "zero_exalt", "zero_other", "zero_uncertain"), "Yes","No")} -> Yes | AN38: =1 + COUNTIF($V$2:V37,"main") -> 10 | AO38: =IF($A38="","",IF($AH38=$AH39,$V39,"")) -> nominalised | AP38: =IF(OR($V38="relative",$V38="nominalised"),0,1) -> 1 | AQ38: =IF(AP39=0,"",COUNTIFS($AN$2:$AN39,$AN39,$AP$2:$AP39,1)) | AR38: =IF(AQ38=1,1,0) -> 0 | AS38: overt | AT38: n/a | AU38: =IF(AND($O38="overt",LEFT($AS38,5)="zero_"),1,0) -> 0 | AV38: =IF(AND($Q38="overt",LEFT($AT38,5)="zero_"),1,0) -> 0
A39: Heike 2.38 | B39: 空柱より内鈴の綱の辺に布衣の者の候ふ (sorabashira yori uchisuzu no tsuna no hen ni hoi no mono no soroou) | C39: that one wearing unsuitable costume should be within the balustrade of the steps of the Court near the bell-rope of the library, | D39: 候ふ | E39: indicative | F39: other | G39: verb | H39: intransitive | I39: active | J39: positive | K39: 1 | L39: 1 | M39: SUB | N39: 1 | O39: overt | P39: 3 | Q39: n/a | R39: n/a | S39: 0 | T39: 0 | U39: SUB | V39: nominalised | W39: 1 | X39: 0 | Y39: sub | Z39: lexical_humble_verb | AA39: 0 | AB39: none | AC39: te | AD39: =IF(V39<>"te","", IF(OR(AC39="",AC39<>"te"), "te_initial", "te_medial")) | AE39: ss | AF39: ss | AG39: topic-shift | AH39: contains_new | AI39: internally headed | AK39: =L39/K39 -> 1 | AL39: =IF(OR(G39="LVC", G39="LVC (j)", G39="LVC (inf)"), "LVC","non-LVC") -> non-LVC | AM39: {=IF(OR(O39:O196="zero_recoverable", "zero_exalt", "zero_other", "zero_uncertain"), "Yes","No")} -> Yes | AN39: =1 + COUNTIF($V$2:V38,"main") -> 10 | AO39: =IF($A39="","",IF($AH39=$AH40,$V40,"")) | AP39: =IF(OR($V39="relative",$V39="nominalised"),0,1) -> 0 | AQ39: =IF(AP40=0,"",COUNTIFS($AN$2:$AN40,$AN40,$AP$2:$AP40,1)) -> 2 | AR39: =IF(AQ39=1,1,0) -> 0 | AS39: overt | AT39: n/a | AU39: =IF(AND($O39="overt",LEFT($AS39,5)="zero_"),1,0) -> 0 | AV39: =IF(AND($Q39="overt",LEFT($AT39,5)="zero_"),1,0) -> 0
A40: Heike 2.39 | B40: は何者ぞ wa nani mono zo | C40: and wondering who he was. | D40: 何者ぞ | E40: indicative | F40: other | G40: copula | H40: intransitive | I40: active | J40: positive | K40: 1 | L40: 1 | M40: SUB | N40: 0 | O40: overt | P40: 3 | Q40: n/a | R40: n/a | S40: 0 | T40: 0 | U40: n/a | V40: main | W40: 0 | X40: 0 | Y40: n/a | Z40: n/a | AA40: 0 | AB40: none | AC40: nominalised | AD40: =IF(V40<>"te","", IF(OR(AC40="",AC40<>"te"), "te_initial", "te_medial")) | AE40: ss | AF40: ss | AG40: topic-continued | AH40: all given | AK40: =L40/K40 -> 1 | AL40: =IF(OR(G40="LVC", G40="LVC (j)", G40="LVC (inf)"), "LVC","non-LVC") -> non-LVC | AM40: {=IF(OR(O40:O197="zero_recoverable", "zero_exalt", "zero_other", "zero_uncertain"), "Yes","No")} -> Yes | AN40: =1 + COUNTIF($V$2:V39,"main") -> 10 | AO40: =IF($A40="","",IF($AH40=$AH41,$V41,"")) | AP40: =IF(OR($V40="relative",$V40="nominalised"),0,1) -> 1 | AQ40: =IF(AP41=0,"",COUNTIFS($AN$2:$AN41,$AN41,$AP$2:$AP41,1)) -> 1 | AR40: 0 | AS40: zero_other | AT40: n/a | AU40: =IF(AND($O40="overt",LEFT($AS40,5)="zero_"),1,0) -> 1 | AV40: =IF(AND($Q40="overt",LEFT($AT40,5)="zero_"),1,0) -> 0
...

Sheet Prelim Analysis
A1: 1. RD vs argument realisation and structure
A3: 1.1 RD and overt vs omitted arguments
A4: Object_Class | B4: Average of RD2 | C4: Count of Clause_ID
A5: n/a | B5: 0.7012987 | C5: 78
A6: not_applicable | B6: 0 | C6: 2
A7: overt | B7: 1.4210526 | C7: 56
A8: zero_other | B8: 0.75 | C8: 4
A9: zero_recoverable | B9: 0.72727273 | C9: 11
A10: zero_uncertain | B10: 1 | C10: 1
A11: Grand Total | B11: 0.96710526 | C11: 152
A16: Arg Type | B16: Average of RD2
A17: IO | B17: 1.0714286 | D17: Predicate_Transitivity | E17: Average of RD2 | G17: Sum of RD2 | H17: Predicate_Transitivity
A18: n/a | B18: 0 | D18: ditransitive | E18: 1.5 | G18: Verb_Semantic_Class | H18: ditransitive | I18: intransitive | J18: transitive | K18: Grand Total
A19: O (Speech) | B19: 1 | D19: intransitive | E19: 0.71764706 | G19: action | I19: 12 | J19: 32 | K19: 44
A20: O (Speech) +IO | B20: 2 | D20: transitive | E20: 1.2727273 | G20: aux/modal | I20: 2 | K20: 2
A21: O+IO | B21: 2 | D21: (blank) | E21: 0.98701299 | G21: communication | H21: 1 | I21: 1 | J21: 4 | K21: 6
A22: OBJ | B22: 1.0333333 | D22: Grand Total | E22: 0.96757436 | G22: motion | I22: 2 | J22: 3 | K22: 5
A23: S (Speech) | B23: 1 | G23: other | H23: 2 | I23: 18 | J23: 31 | K23: 51
A24: S+O | B24: 2 | G24: perception | I24: 0 | J24: 6 | K24: 6
A25: S+O (Speech) | B25: 2 | G25: psych-state | I25: 4 | J25: 4 | K25: 8
A26: S+O+IO | B26: 3 | G26: stative | I26: 22 | J26: 4 | K26: 26
A27: SUB | B27: 1 | G27: Grand Total | H27: 3 | I27: 61 | J27: 84 | K27: 148
A28: (blank) | B28: 0.97402597
A29: Grand Total | B29: 0.96757436
A33: 2. Exaltation and pro-drop | O33: Pivot 7: RD2 × Exaltation_Present
A35: 2.1 Exaltation vs Arg Type
A36: Average of RD2 | B36: EXALT INSIG | H36: Average of RD2 | I36: V-ARG-Ø-ARG | O36: V-ARG-Ø-ARG | P36: Average of RD2
A37: Arg Type | B37: 0 | C37: 1 | D37: Grand Total | H37: Arg Type | I37: 0 | J37: 1 | K37: Grand Total | O37: 0 | P37: 1.0491803
A38: IO | B38: 1.0769231 | C38: 1 | D38: 1.0714286 | H38: IO | I38: 1.0909091 | J38: 1 | K38: 1.0714286 | O38: 1 | P38: 0.65625
A39: O (Speech) | B39: 1 | D39: 1 | H39: O (Speech) | I39: 1 | J39: 1 | K39: 1 | O39: 32 | P39: 0.97402597
A40: O (Speech) +IO | C40: 2 | D40: 2 | H40: O (Speech) +IO | I40: 2 | K40: 2 | O40: (blank)
A41: O+IO | B41: 2 | D41: 2 | H41: O+IO | I41: 2 | J41: 2 | K41: 2 | O41: Grand Total | P41: 0.96757436
A42: OBJ | B42: 1.0344828 | C42: 1 | D42: 1.0333333 | H42: OBJ | I42: 1.0555556 | J42: 1 | K42: 1.0333333
A43: S (Speech) | B43: 1 | D43: 1 | H43: S (Speech) | I43: 1 | K43: 1 | O43: EXALT INSIG | P43: Average of RD2
A44: S+O | B44: 2 | C44: 2 | D44: 2 | H44: S+O | I44: 2 | K44: 2 | O44: 0 | P44: 0.92592593
A45: S+O (Speech) | C45: 2 | D45: 2 | H45: S+O (Speech) | I45: 2 | K45: 2 | O45: 1 | P45: 1.2631579
A46: S+O+IO | B46: 3 | D46: 3 | H46: S+O+IO | I46: 3 | K46: 3 | O46: 19 | P46: 0.97402597
A47: SUB | B47: 1 | C47: 1 | D47: 1 | H47: SUB | I47: 1 | K47: 1 | O47: (blank)
A48: Grand Total | B48: 1.1904762 | C48: 1.2631579 | D48: 1.2016129 | H48: Grand Total | I48: 1.2307692 | J48: 1.05 | K48: 1.2016129 | O48: Grand Total | P48: 0.96757436
B53: V-ARG-Ø-ARG | C53: Values | O53: Average of RD2 | P53: Subject_Zero
...

Sheet RD vs argument realisation
A1: 1. RD vs argument realisation and structure
A2: 1.1 RD and overt vs Cluase Type / Subjects
B3: Clause_Type | C3: Values | V3: Clause_Type | W3: RD2 Average | X3: N | Z3: Clause_Type | AA3: Average of RD2 | AB3: Count of Clause_ID
B4: complement | D4: inf | F4: main | H4: nominalised | J4: none | L4: relative | N4: subordinate | P4: te | R4: Total Count of Clause_ID | S4: Total Average of RD2 | V4: complement | W4: 1 | X4: 8 | Z4: 0 | AA4: 0.97402597 | AB4: 1
A5: Subject_Class | B5: Count of Clause_ID | C5: Average of RD2 | D5: Count of Clause_ID | E5: Average of RD2 | F5: Count of Clause_ID | G5: Average of RD2 | H5: Count of Clause_ID | I5: Average of RD2 | J5: Count of Clause_ID | K5: Average of RD2 | L5: Count of Clause_ID | M5: Average of RD2 | N5: Count of Clause_ID | O5: Average of RD2 | P5: Count of Clause_ID | Q5: Average of RD2 | V5: inf | W5: 1.3333333 | X5: 6 | Z5: complement | AA5: 1 | AB5: 8
A6: overt | B6: 4 | C6: 1.5 | D6: 2 | E6: 1.5 | F6: 22 | G6: 1.1428571 | H6: 2 | I6: 1 | L6: 10 | M6: 1.2 | N6: 20 | O6: 1.15 | P6: 9 | Q6: 1.8888889 | R6: =SUM(B6,D6,F6,H6,J6,L6,N6,P6) -> 69 | S6: =AVERAGE(Q6,O6,M6,K6,I6,G6,E6,C6) -> 1.3402494 | V6: main | W6: 0.85714286 | X6: 42 | Z6: inf | AA6: 1.3333333 | AB6: 6
A7: zero_exalt | B7: 1 | C7: 1 | D7: 1 | E7: 2 | F7: 9 | G7: 0.6 | L7: 2 | M7: 0.5 | N7: 9 | O7: 0.44444444 | P7: 6 | Q7: 1 | R7: =SUM(B7,D7,F7,H7,J7,L7,N7,P7) -> 28 | S7: =AVERAGE(Q7,O7,M7,K7,I7,G7,E7,C7) -> 0.92407407 | V7: nominalised | W7: 1 | X7: 2 | Z7: main | AA7: 0.85714286 | AB7: 42
