Workbook

Sheet Tosa
A1: Clause | B1: Translation | C1: Predicate | D1: ~Ø-Verbal | E1: ACT-ARG | F1: NON-ARG | G1: V-ARG-Ø-ARG | H1: GAP-NON-ARG | I1: GAP-ACT-ARG | J1: comments
A2: Otoko mo sunaru | B2: It is generally a man who writes | C2: sunaru | D2: 1 | E2: 1 | F2: 0 | G2: 0 | H2: 0 | I2: 1
A3: nikki to iu mono o, onna mo shite mimu | B3: what is called a Diary, but now a woman will see what she can do. | C3: shitemimu | D3: 1 | E3: 2 | F3: 0 | G3: 0 | H3: 0 | I3: 0
A4: tote suru nari. | B4: NA | C4: surunari | D4: 1 | E4: 0 | F4: 0 | G4: 0 | H4: 0 | I4: 0
A5: Sore no toshi (Jōhei yonen) no shihasu no hatsuka amari ichinichi no, inu no toki ni kadode su. | B5: One year, on the twenty-first day of the twelfth month, a certain personage left home at the Hour of the Dog (8:00 PM). | C5: kadode su | D5: 1 | E5: 0 | F5: 1 | G5: 0 | H5: 0 | I5: 0
A6: Sono yoshi isasaka mono ni kakitsuku. | B6: This was the beginning of this modest record. | C6: kakitsuku | D6: 1 | E6: 1 | F6: 0 | G6: 0 | H6: 0 | I6: 0
A7: Aru hito agata no yonen gonen hatete | B7: He had just completed the usual period of four or five years as Governor of a Province. | C7: hatete | D7: 1 | E7: 1 | F7: 0 | G7: 0 | H7: 0 | I7: 0
A8: rei no koto domo mina shi oete, | B8: Everything had been wound up, documents, | C8: shioete | D8: 1 | E8: 1 | F8: 0 | G8: 0 | H8: 0 | I8: 0
A9: geyu nado torite | B9: &c., had been handed over. | C9: torite | D9: 1 | E9: 1 | F9: 0 | G9: 0 | H9: 0 | I9: 0
A10: sumu | C10: sumu | D10: 1 | E10: 0 | F10: 0 | G10: 0 | H10: 0 | I10: 1
A11: tachi yori idete | B11: He was now about to go down to the place of embarkation. | C11: idete | D11: 1 | E11: 1 | F11: 0 | G11: 0 | H11: 0 | I11: 0
A12: fune ni noru | B12: travel on shipboard. | C12: noru | D12: 1 | E12: 1 | F12: 0 | G12: 0 | H12: 0 | I12: 0
A13: beki tokoro e wataru. | B13: For he was to | C13: wataru | D13: 1 | E13: 1 | F13: 0 | G13: 0 | H13: 0 | I13: 0
A14: Kare kore shiru/shiranu | B14: both friends and strangers | C14: shiru | D14: 1 | E14: 1 | F14: 0 | G14: 0 | H14: 0 | I14: 0 | J14: not sure whether internal heads should be treated the same way as other heads/ kare kore
A15: okuri su | B15: came to see him off. | C15: okuri su | D15: 1 | E15: 0 | F15: 0 | G15: 0 | H15: 0 | I15: 0
A16: Toshigoro yoku kurabeshitsuru | B16: Including many who had served him faithfully during the past years. | C16: kurabeshitsuru | D16: 1 | E16: 0 | F16: 1 | G16: 0 | H16: 0 | I16: 0 | J16: not sure whether internal heads should be treated the same way as other heads
A17: wakaregataku omohite | B17: [These loyal attendants] sorrowed at the thought of losing him | C17: omohite | D17: 1 | E17: 0 | F17: 0 | G17: 0 | H17: 0 | I17: 0 | J17: ?
A18: sono hi shikashika ni tokaku shitsutsu | B18: that day There was endless bustle and confusion | C18: shitsutsu | D18: 1 | E18: 1 | F18: 2 | G18: 0 | H18: 0 | I18: 0
A19: nonoshiru | B19: and so with one thing and another | C19: nonoshiru | D19: 1 | E19: 0 | F19: 0 | G19: 0 | H19: 0 | I19: 0
A20: uchi ni yofukenu. | B20: the night drew on.” | C20: yofukenu | D20: 1 | E20: 0 | F20: 1 | G20: 0 | H20: 0 | I20: 0
A21: Nijūnichi, Izumi no kuni made to tairaka ni negaitatsu. | B21: 22nd day—He prayed for a calm voyage to the Land of Izumi | C21: negaitsutsu | D21: 1 | E21: 0 | F21: 1 | G21: 0 | H21: 0 | I21: 0
A22: Fujiwara no Kotozane funaji naredo | B22: although he was to travel by sea | C22: naredo | D22: 1 | E22: 1 | F22: 0 | G22: 0 | H22: 0 | I22: 0
A23: uma no hanamuke su. | B23: Fujiwara no Tokisanē came to turn his horse's head' | C23: hanamuke su | D23: 1 | E23: 0 | F23: 0 | G23: 0 | H23: 0 | I23: 0
A24: Jōchūge nagara yoihamasugite | B24: Upper, middle, and lower classes all drank too heavily | C24: yoihamasugite | D24: 1 | E24: 1 | F24: 0 | G24: 0 | H24: 0 | I24: 0
A25: ito ayashiku shiho umi no hotori nite azareaeri. | B25: and, wonderful to relate, there they were on the edge of the salt sea itself all useless and incompetent! | C25: azareaeri | D25: 1 | E25: 0 | F25: 1 | G25: 0 | H25: 0 | I25: 0
A26: Nijūsannichi, Yagi no Yasukyō to iu hito ari. | B26: 23 JAN. A certain man, called Yagi no Yasunori | C26: ari | D26: 1 | E26: 1 | F26: 1 | G26: 0 | H26: 0 | I26: 0
A27: Kono hito kuni ni kanarazu shimo iitsukau | B27: of too high rank to have been one of his regular attendants in the Province | C27: iitsukau | D27: 1 | E27: 2 | F27: 0 | G27: 0 | H27: 0 | I27: 0
A28: mono ni mo arazaru nari. | B28: although he was | C28: nari | D28: 1 | E28: 1 | F28: 0 | G28: 0 | H28: 0 | I28: 0
A29: Kore zo tadashiki yō nite uma no hanamuke shitaru. | B29: openly made him a farewell present | C29: shitaru | D29: 1 | E29: 1 | F29: 1 | G29: 0 | H29: 0 | I29: 0
... A53: Yamato uta aruji no mori no yomerikeri: | B53: but the following is the Japanese verse composed by the Governor, as host | C53: yomerikeri | D53: 1 | E53: 2 | F53: 0 | G53: 0 | H53: 0 | I53: 0
A54: "Miyako idete | B54: From the Capital Far I came
A55: kimi ni ahamu | B55: to see my Lord
A56: tokoshimono wo koshikai mo naku | B56: across the sea, 'twas all in vain
A57: wakarenuru kana." | B57: For we now must part again
A58: Kaeru | B58: in reply
A59: mae no mori no yomerikeri: | B59: Whereupon the former Governor' composed this
A60: "Shiratahe no namiji o tōku yukihahite | B60: I, too, traveled far O'er the stormy road of waves White with crested foam
A61: ware ni nibeki wa tare naranaku ni." | B61: Scare, I think, another man Would have faced the risks we ran
A62: Koto hitobito no mo arikere do | B62: There were also verses composed by many others | C62: arikeredo | D62: 1 | E62: 1 | F62: 0 | G62: 0 | H62: 0 | I62: 0
A63: sakashiki mo nakarubeshi. | B63: but they were quite worthless | C63: nakarubeshi | D63: 1 | E63: 0 | F63: 0 | G63: 0 | H63: 0 | I63: 0
...

Sheet Genji
A1: Clause | B1: Translation | C1: Predicate | D1: ~Ø-Verbal | E1: ACT-ARG | F1: NON-ARG | G1: V-ARG-Ø-ARG | H1: GAP-NON-ARG | I1: GAP-ACT-ARG | J1: NMLZ head | K1: NOM EXH MORPH | L1: Сomment
A2: Izure no Ohotoki ni ka. Nyōgo, Kōi amata saburai tamai keru | B2: In the reign of a certain Emperor, whose name is unknown to us, there was, among the Niogo and Kôyi of the Imperial Court | C2: saburai tamai keru | D2: 1 | E2: 0 | F2: 2 | G2: 1 | H2: 1 | I2: 0
A3: naka ni, ito yangotonaki kiwa ni wa aranu ga | B3: one who, though she was not of high birth | C3: aranu | D3: 1 | E3: 1 | F3: 0 | G3: 0 | H3: 0 | I3: 0
A4: sugurete tokimeki tama- | B4: enjoyed the full tide of Royal favor | C4: tokimeki tamau | D4: 1 | E4: 0 | F4: 0 | G4: 1 | H4: 0 | I4: 1 | J4: 1
A5: ...u ari keri | B5: there was | C5: ari keri | D5: 1 | E5: 1 | F5: 0 | G5: 0 | H5: 0 | I5: 0
A6: Hajime yori, ware wa to omoiagari tamai keru | B6: Hence […] had always been thinking — "I shall be the one," | C6: omoiagari tamai keru | D6: 1 | E6: 1 | F6: 1 | G6: 1 | H6: 0 | I6: 1
A7: o-kata gata, mezamashiki mono ni otoshime | B7: [her superiors, each one of whom] gazed upon her disdainfully | C7: otoshime | D7: 1 | E7: 1 | F7: 1 | G7: 0 | H7: 0 | I7: 0
A8: sonemi tamau | B8: with malignant eyes, | C8: sonemi tamau | D8: 1 | E8: 0 | F8: 0 | G8: 1 | H8: 0 | I8: 0
A9: Onaji hodo, sore yori gerō no Kōi-tachi wa, mashite yasukarazu | B9: and her equals and inferiors were more indignant still. | C9: yasukarazu | D9: 1 | E9: 1 | F9: 1 | G9: 0 | H9: 0 | I9: 0
A10: Asayū no miyazuki ni tsukete mo, | B10: The way she waited on him day after day | C10: tsukete mo | D10: 1 | E10: 1 | F10: 0 | G10: 0 | H10: 0 | I10: 0
A11: hito no kokoro o ugokashi | B11: only stirred up feeling against her | C11: ugokashi | D11: 1 | E11: 1 | F11: 0 | G11: 0 | H11: 0 | I11: 0
A12: urami o ou | B12: burden of resentment | C12: ou | D12: 1 | E12: 1 | F12: 0 | G12: 0 | H12: 1 | I12: 0
A13: tsumori ni ya ari kemu | B13: was what | C13: ari kemu | D13: 1 | E13: 1 | F13: 0 | G13: 0 | H13: 0 | I13: 0
A14: ito atsushiku nariyuki | B14: affected her health | C14: nariyuki | D14: 1 | E14: 0 | F14: 0 | G14: 0 | H14: 0 | I14: 0
A15: monogokorobosoge ni sato-gachinaru o | B15: and obliged her often to withdraw in misery to her home | C15: sato-gachinaru | D15: 1 | E15: 0 | F15: 0 | G15: 0 | H15: 0 | I15: 0 | J15: 1
A16: iyoiyo akazu | B16: who could less and less do without her | C16: akazu | D16: 1 | E16: 0 | F16: 0 | G16: 0 | H16: 0 | I16: 0
A17: aware naru | C17: naru | D17: 1 | E17: 0 | F17: 0 | G17: 0 | H17: 0 | I17: 1
A18: mono ni obobosete | C18: obobosete | D18: 1 | E18: 0 | F18: 0 | G18: 0 | H18: 0 | I18: 0
A19: hito no soshiri o mo e habakara se tamawazu | B19: ignored his critics | C19: habakara se tamawazu | D19: 1 | E19: 1 | F19: 0 | G19: 1 | H19: 0 | I19: 0
A20: yo no tameshi ni mo narinubeki | B20: until his behavior seemed bound | C20: narinubeki | D20: 1 | E20: 1 | F20: 0 | G20: 0 | H20: 0 | I20: 1
A21: o-motenashi nari | B21: to be the talk of all | C21: nari | D21: 1 | E21: 0 | F21: 0 | G21: 0 | H21: 0 | I21: 0
A22: Kandachime, Uebito nado mo, ainaku me o sobame tsutsu | B22: the senior nobles and privy gentlemen could only avert their eyes | C22: sobametsutsu | D22: 1 | E22: 2 | F22: 0 | G22: 0 | H22: 0 | I22: 0
A23: chichi no Dainagon wa nakunari te | B23: From this sad spectacle | C23: nakunari te | D23: 1 | E23: 1 | F23: 0 | G23: 0 | H23: 0 | I23: 0
A24: Morokoshi ni mo, shikaru koto no okori ni koso yo mo midare | B24: even in China such things had led to disorder and ruin | C24: midare | D24: 1 | E24: 1 | F24: 2 | G24: 0 | H24: 0 | I24: 0
A25: ashikarikere to | C25: ashikarikere | D25: 1 | E25: 0 | F25: 0 | G25: 0 | H25: 0 | I25: 0
A26: yōyō ame no shita ni mo ajikinau | B26: and as discontent spread through the realm | C26: ajikinau | D26: 1 | E26: 0 | F26: 1 | G26: 0 | H26: 0 | I26: 0
A27: hito no motenayami-gusa ni narite | B27: with many a painful consequence for the lady herself | C27: narite | D27: 1 | E27: 1 | F27: 0 | G27: 0 | H27: 0 | I27: 0
A28: Yōkihi no tameshi mo hikiide | B28: the example of Yokihi^ came more and more to mind | C28: hikiide | D28: 1 | E28: 1 | F28: 0 | G28: 0 | H28: 0 | I28: 0
A29: tsubeu nariyuku ni | C29: nariyuku | D29: 1 | E29: 0 | F29: 0 | G29: 0 | H29: 0 | I29: 0
A30: ito hashitanaki koto ōkaredo | B30: with many a painful consequence | C30: ōkaredo | D30: 1 | E30: 1 | F30: 0 | G30: 0 | H30: 0 | I30: 0
A31: katajikenaki on-kokorobae no tagui na | C31: naki | D31: 1 | E31: 1 | F31: 0 | G31: 0 | H31: 0 | I31: 0
A32: [ki] o tanomi ni te | C32: tanomi ni te | D32: 1 | E32: 1 | F32: 0 | G32: 0 | H32: 0 | I32: 0
A33: majirai tamau | C33: majirai tamau | D33: 1 | E33: 0 | F33: 0 | G33: 1 | H33: 0 | I33: 0
A34: Chichi no Dainagon wa nakunari te | B34: The Grand Counsellor, her father, was gone | C34: nakunari te | D34: 1 | E34: 1 | F34: 0 | G34: 0 | H34: 0 | I34: 0
A35: Haha Kita no Kata namu inishie no hito no yoshi aru nite | B35: and it was her mother, a lady from an old family, | C35: aru nite | D35: 1 | E35: 1 | F35: 0 | G35: 0 | H35: 0 | I35: 0
A36: oya uchigu shi | B36: whose parents were both alive | C36: gu shi | D36: 1 | E36: 1 | F36: 0 | G36: 0 | H36: 0 | I36: 0
A37: sashiatarite yo no oboe hanayakana ru | B37: and who enjoyed general esteem | C37: hanayakana ru | D37: 1 | E37: 1 | F37: 0 | G37: 0 | H37: 1 | I37: 0
A38: o-kata gata ni mo otorazu | B38: no less than others | C38: otorazu | D38: 1 | E38: 1 | F38: 0 | G38: 0 | H38: 0 | I38: 0
A39: nanigoto no gishiki o mo motenashi tamai keredo | B39: give to court events | C39: motenashi tamai | D39: 1 | E39: 1 | F39: 0 | G39: 1 | H39: 0 | I39: 0
A40: toritate te wa kabashiki on-ushiromi shi nakereba | C40: nakereba | D40: 1 | E40: 1 | F40: 0 | G40: 0 | H40: 0 | I40: 0
...

Sheet Stats
B1: TOSA
B2: =Tosa!A109 -> RD2 | C2: =Tosa!B109 -> 0.81818182 | D2: =Tosa!C109 -> ACT-ARG/~Ø-Verbal
B3: =Tosa!A110 -> RD2+ | C3: =Tosa!B110 -> 0.81818182 | D3: =Tosa!C110 -> (ACT-ARG+V-ARG-Ø-ARG)/~Ø-Verbal
B4: =Tosa!A111 -> RD2++ | C4: =Tosa!B111 -> 0.89772727 | D4: =Tosa!C111 -> (ACT-ARG+GAP-ACT-ARG)/~Ø-Verbal
B5: =Tosa!A112 -> RD2+++ | C5: =Tosa!B112 -> 0.89772727 | D5: =Tosa!C112 -> (ACT-ARG+V-ARG-Ø-ARG+GAP-ACT-ARG)/~Ø-Verbal
B6: =Tosa!A113 -> RD2- | C6: =Tosa!B113 -> 0 | D6: =Tosa!C113 -> V-ARG-Ø-ARG/~Ø-Verbal
B10: GENJI
B11: =Genji!A103 -> RD2 | C11: =Genji!B103 -> 0.62 | D11: =Genji!C103 -> ACT-ARG/~Ø-Verbal
B12: =Genji!A104 -> RD2+ | C12: =Genji!B104 -> 0.87 | D12: =Genji!C104 -> (ACT-ARG+V-ARG-Ø-ARG)/~Ø-Verbal
B13: =Genji!A105 -> RD2++ | C13: =Genji!B105 -> 0.73 | D13: =Genji!C105 -> (ACT-ARG+GAP-ACT-ARG)/~Ø-Verbal
B14: =Genji!A106 -> RD2+++ | C14: =Genji!B106 -> 0.98 | D14: =Genji!C106 -> (ACT-ARG+V-ARG-Ø-ARG+GAP-ACT-ARG)/~Ø-Verbal
B15: =Genji!A107 -> RD2- | C15: =Genji!B107 -> 0.25 | D15: =Genji!C107 -> V-ARG-Ø-ARG/~Ø-Verbal
