Workbook

Sheet Isopo
A1: Clause | B1: Translation | C1: Predicate | D1: ~Ø-Verbal | E1: ACT-ARG | F1: NON-ARG | G1: EXALT INSIG | H1: V-ARG-Ø-ARG | I1: GAP-NON-ARG | J1: GAP-ACT-ARG | K1: NMLZ head | L1: NOM EXH MORPH | M1: Сomment
A2: EVROPA no vchi Phrigiatoyŭ cunino Troia toyŭ jŏrino qinpenni Amoniato yŭ ſatoga vogiaru. | B2: ＥＶＲＯＰＡの内Ｐｈｒｉｇｉａと言う国のＴｒｏｉａと言う城裡の近辺にＡｍｏｎｉａと言う里がおぢゃる | C2: vogiaru | D2: 1 | E2: 1 | F2: 1 | G2: 0 | H2: 0 | I2: 0 | J2: 0 | K2: 0 | L2: 0
A3: [...] nauoba Eſopoto yŭte | B3: その里に名をばＥｓｏｐｏと言うて | C3: yŭte | D3: 1 | E3: 1 | F3: 0 | G3: 0 | H3: 0 | I3: 0 | J3: 0 | K3: 0 | L3: 0
A4: [Sono ſatoni] yguiŏ fuxiguina jintaiga vogiattaga | B4: 異形不思議な人体がおぢゃったが | C4: vogiattaga | D4: 1 | E4: 1 | F4: 1 | G4: 0 | H4: 0 | I4: 0 | J4: 0 | K4: 0 | L4: 0
A5: [...] cono fitoni maſatte | B5: Ｅｕｒｏｐａの天下にこの人に勝って | C5: maſatte | D5: 1 | E5: 1 | F5: 0 | G5: 0 | H5: 0 | I5: 0 | J5: 0 | K5: 0 | L5: 0
A6: [ſono jidai Europano tencani] minicui mo nomo vorinacatta | B6: 醜い者もおりなかった | C6: vorinacatta | D6: 1 | E6: 2 | F6: 1 | G6: 0 | H6: 0 | I6: 0 | J6: 0 | K6: 0 | L6: 0 | M6: is oru an EX verb in LMJ?
A7: to qicoyeta | B7: と聞こえた | C7: qicoyeta | D7: 1 | E7: 1 | F7: 0 | G7: 0 | H7: 0 | I7: 0 | J7: 0 | K7: 0 | L7: 0
A8: Mazzu cŏbeua togari | B8: 先づ頭は尖り， | C8: togari | D8: 1 | E8: 1 | F8: 0 | G8: 0 | H8: 0 | I8: 0 | J8: 0 | K8: 0 | L8: 0
A9: manacoua tçubô xicamo dete | B9: 眼はつぼう然も出て | C9: dete | D9: 1 | E9: 1 | F9: 0 | G9: 0 | H9: 0 | I9: 0 | J9: 0 | K9: 0 | L9: 0
A10: fitomi no ſaqiua tairacani, | B10: 瞳の先は平らかに， | C10: tairacani | D10: 1 | E10: 1 | F10: =-G98 -> 0 | G10: 0 | H10: 0 | I10: 0 | J10: 0 | K10: 0 | L10: 0
A11: riŏno fôua tare | B11: 両の頬は垂れ | C11: tare | D11: 1 | E11: 1 | F11: 0 | G11: 0 | H11: 0 | I11: 0 | J11: 0 | K11: 0 | L11: 0
A12: cubiua yugami | B12: 首は歪み | C12: yugami | D12: 1 | E12: 1 | F12: 0 | G12: 0 | H12: 0 | I12: 0 | J12: 0 | K12: 0 | L12: 0
A13: taqe-ua ficŭ | B13: 丈は低う | C13: ficŭ | D13: 1 | E13: 1 | F13: 0 | G13: 0 | H13: 0 | I13: 0 | J13: 0 | K13: 0 | L13: 0
A14: yocobarini,xeua cugumi | B14: 横張りに，背は屈み | C14: cugumi | D14: 1 | E14: 1 | F14: 0 | G14: 0 | H14: 0 | I14: 0 | J14: 0 | K14: 0 | L14: 0
A15: faraua fare | B15: 腹は腫れ | C15: fare | D15: 1 | E15: 1 | F15: 0 | G15: 0 | H15: 0 | I15: 0 | J15: 0 | K15: 0 | L15: 0
A16: taredete | B16: 垂れ出て | C16: taredete | D16: 1 | E16: 0 | F16: 0 | G16: 0 | H16: 0 | I16: 0 | J16: 0 | K16: 0 | L16: 0
A17: cotobaua domoride vogiatta | B17: 言葉は吃りでおぢゃった | C17: de vogiatta | D17: 1 | E17: 1 | F17: 0 | G17: 0 | H17: 0 | I17: 0 | J17: 0 | K17: 0 | L17: 0
A18: Corerano ſugata vomotte | B18: これ等の姿を持って | C18: vomotte | D18: 1 | E18: 1 | F18: 0 | G18: 0 | H18: 0 | I18: 0 | J18: 0 | K18: 0 | L18: 0
A19: minicui coto tenca busŏ de atta | B19: 醜い事天下無双で有った | C19: de atta | D19: 1 | E19: 1 | F19: 1 | G19: 0 | H19: 0 | I19: 0 | J19: 0 | K19: 0 | L19: 0
A20: gotoqu chiyeno taqeta | B20: ごとく，知恵の長けた | C20: yararureba | D20: 1 | E20: 1 | F20: 1 | G20: 0 | H20: 0 | I20: 0 | J20: 0 | K20: 0 | L20: 0
A21: monomo cono fitoni narabu | B21: 者もこの人に並ぶ | C21: narabu | D21: 1 | E21: 2 | F21: 0 | G21: 0 | H21: 0 | I21: 1 | J21: 0 | K21: 0 | L21: 0
A22: cotoua vorinacatta | B22: 事はおりなかった | C22: vorinacatta | D22: 1 | E22: 1 | F22: 0 | G22: 0 | H22: 0 | I22: 0 | J22: 0 | K22: 0 | L22: 0
... A24: yŏ-ua:cugaino ſabaqi aruiua naixôno toriatçucai nadoua icanimo niyŏmajij | B24: 様は：公界の捌き或いは内証の取り扱いなどは如何にも似合うまじい | C24: niyŏmajij | D24: 1 | E24: 1 | F24: 1 | G24: 0 | H24: 0 | I24: 0 | J24: 0 | K24: 0 | L24: 0
A25: to miyureba | B25: と見ゆれば | C25: miyureba | D25: 1 | E25: 1 | F25: 0 | G25: 0 | H25: 0 | I25: 0 | J25: 0 | K25: 0 | L25: 0 | M25: should the -to part be considered a clausal subject of miyureba?
A26: xemete nônin no xoſauo naritomo ategauŏzu | B26: せめて農人の所作をなりともあてがわうず | C26: ategauŏzu | D26: 1 | E26: 1 | F26: 0 | G26: 0 | H26: 0 | I26: 0 | J26: 0 | K26: 0 | L26: 0
A27: to vomoi ſadame | B27: と思い定め | C27: vomoi ſadame | D27: 1 | E27: 1 | F27: 0 | G27: 0 | H27: 0 | I27: 0 | J27: 0 | K27: 0 | L27: 0 | M27: should the -to part be considered a clausal subject?
A28: nôguuo coxiraye atayete | B28: 農具を拵え与えて | C28: atayete | D28: 1 | E28: 1 | F28: 0 | G28: 0 | H28: 0 | I28: 0 | J28: 0 | K28: 0 | L28: 0
A29: denbacu ye yararureba | B29: 田畠へ遣らるれば | C29: yararureba | D29: 1 | E29: 1 | F29: 0 | G29: 0 | H29: 1 | I29: 0 | J29: 0 | K29: 0 | L29: 0
A30: Eſopomomata cocoroyogueni ſono xoſauo naita | B30: Ｅｓｏｐｏも又快気にその所作を成いた． | C30: naita | D30: 1 | E30: 2 | F30: 0 | G30: 0 | H30: 0 | I30: 0 | J30: 0 | K30: 0 | L30: 0
A31: Xicareba fodofete cano xujin ſono denbacu uo mimaini ideraretareba | B31: 然れば程経てかの主人その田畠を見舞いに出でられたれば | C31: ideraretareba | D31: 1 | E31: 2 | F31: 0 | G31: 1 | H31: 0 | I31: 0 | J31: 0 | K31: 0 | L31: 0
A32: aru fiacuxŏ jŏjŏno jucuxiuo motteqite | B32: 或る百姓上々の熟柿を持って来て | C32: motteqite | D32: 1 | E32: 2 | F32: 0 | G32: 0 | H32: 0 | I32: 0 | J32: 0 | K32: 0 | L32: 0
A33: xujinni ſaſagureba | B33: 主人に捧ぐれば | C33: ſaſagureba | D33: 1 | E33: 1 | F33: 0 | G33: 0 | H33: 1 | I33: 0 | J33: 0 | K33: 0 | L33: 0
A34: irocamo ychidan yôte | B34: 色香も一段良うて | C34: yôte | D34: 1 | E34: 1 | F34: 0 | G34: 0 | H34: 0 | I34: 0 | J34: 0 | K34: 0 | L34: 0
A35: migotoniatta | B35: 見事に有った | C35: niatta | D35: 1 | E35: 0 | F35: 0 | G35: 0 | H35: 0 | I35: 0 | J35: 0 | K35: 0 | L35: 0
A36: ni yotte yorocobi | B36: に因って喜び | C36: yorocobi | D36: 1 | E36: 0 | F36: 1 | G36: 0 | H36: 0 | I36: 0 | J36: 0 | K36: 0 | L36: 0
A37: nanome narananda | B37: 斜めならなんだ | C37: narananda | D37: 1 | E37: 0 | F37: 0 | G37: 0 | H37: 0 | I37: 0 | J37: 0 | K37: 0 | L37: 0
A38: tadaima xŏquan xôzuredomo | B38: 只今賞翫せうずれども | C38: xôzuredomo | D38: 1 | E38: 0 | F38: 1 | G38: 0 | H38: 0 | I38: 0 | J38: 0 | K38: 0 | L38: 0
A39: furoye ireba | B39: 風呂へ入れば | C39: ireba | D39: 1 | E39: 1 | F39: 0 | G39: 0 | H39: 0 | I39: 0 | J39: 0 | K39: 0 | L39: 0
... A64: icaſama cono tatari ga arŏzu | B64: 如何様この祟りが有らうずと | C64: arŏzuto | D64: 1 | E64: 1 | F64: 0 | G64: 0 | H64: 0 | I64: 0 | J64: 0 | K64: 0 | L64: 0
A65: to ſaſayaqimauatta | B65: 囁き回った | C65: ſaſayaqimauatta | D65: 1 | E65: 1 | F65: 0 | G65: 0 | H65: 0 | I65: 0 | J65: 0 | K65: 0 | L65: 0 | M65: should the -to part be considered a clausal complement?
...

Sheet Sheet1

Sheet Stats
B3: Isopo
B4: =Isopo!A103 -> RD2 | C4: =Isopo!B103 -> 0.8989899 | D4: =Isopo!C103 -> ACT-ARG/~Ø-Verbal
B5: =Isopo!A104 -> RD2+ | C5: =Isopo!B104 -> 0.93939394 | D5: =Isopo!C104 -> (ACT-ARG+V-ARG-Ø-ARG)/~Ø-Verbal
B6: =Isopo!A105 -> RD2++ | C6: =Isopo!B105 -> 0.96969697 | D6: =Isopo!C105 -> (ACT-ARG+GAP-ACT-ARG)/~Ø-Verbal
B7: =Isopo!A106 -> RD2+++ | C7: =Isopo!B106 -> 1.010101 | D7: =Isopo!C106 -> (ACT-ARG+V-ARG-Ø-ARG+GAP-ACT-ARG)/~Ø-Verbal
B8: =Isopo!A107 -> RD2- | C8: =Isopo!B107 -> 0.04040404 | D8: =Isopo!C107 -> V-ARG-Ø-ARG/~Ø-Verbal
